Workbook

Sheet BASE DE CONTROL
K1: CORTE DEL 01 AL 15 MARZO | V1: CORTE DEL 16 AL 31 MARZO
A2: FMT-01-INV | D2: RELACION TOMA DE INVENTARIOS DIARIOS | H2: INVENTARIO INICIAL | K2: ENTRADA DEVOLUCION | M2: ENTRADA ALBARAN | O2: SALIDA | Q2: SALDO FINAL | S2: TOMA INVENTARIO | V2: ENTRADA DEVOLUCION | X2: ENTRADA ALBARAN | Z2: SALIDA | AB2: SALDO FINAL | AF2: UBICACIÓN
A3: LINEA | B3: GRUPO | C3: ELEMENTO | D3: ITEM | E3: CONCATENADO | F3: DESCRIPCION | G3: UND MEDIDA | H3: FECHA | I3: CANTIDAD | K3: FECHA RELACION | L3: CANT. | M3: FECHA RELACION | N3: CANT. | O3: FECHA RELACION | P3: CANT. | Q3: FECHA | R3: CANTIDAD | S3: FECHA | T3: CANTIDAD | V3: FECHA RELACION | W3: CANT. | X3: FECHA RELACION | Y3: CANT. | Z3: FECHA RELACION | AA3: CANT. | AB3: FECHA | AC3: CANTIDAD | AD3: SERIAL Nª | AE3: NOTA | AF3: ZONA | AG3: ESTAN | AH3: NIVEL
A4: 1 | B4: 13 | C4: 21 | D4: 180 | E4: =CONCATENATE(B4,"-",C4,"-",D4) -> 13-21-180 | F4: =VLOOKUP(E4,'LISTA ITEMS'!$E$2:$G$875,2,FALSE) -> TACO P/BRIDA BLANCO | G4: =VLOOKUP(E4,'LISTA ITEMS'!$E$2:$G$875,3,FALSE) -> UND | H4: 46083 | I4: 1200 | K4: 46098 | L4: 0 | M4: 46098 | N4: 0 | O4: 46098 | P4: 100 | Q4: 46098 | R4: =+I4+L4+N4-P4 -> 1100 | AC4: =+R4+W4+Y4-AA4 -> 1100 | AF4: 7 | AG4: 2 | AH4: G
A5: 2 | B5: 13 | C5: 21 | D5: 181 | E5: =CONCATENATE(B5,"-",C5,"-",D5) -> 13-21-181 | F5: =VLOOKUP(E5,'LISTA ITEMS'!$E$2:$G$875,2,FALSE) -> TACO P/BRIDA NEGRO | G5: =VLOOKUP(E5,'LISTA ITEMS'!$E$2:$G$875,3,FALSE) -> UND | H5: 46083 | I5: 300 | K5: 46098 | L5: 180 | M5: 46098 | N5: 500 | O5: 46098 | P5: 750 | Q5: 46098 | R5: =+I5+L5+N5-P5 -> 230 | AC5: =+R5+W5+Y5-AA5 -> 230 | AF5: 7 | AG5: 2 | AH5: G
A6: 3 | B6: 13 | C6: 22 | D6: 182 | E6: =CONCATENATE(B6,"-",C6,"-",D6) -> 13-22-182 | F6: =VLOOKUP(E6,'LISTA ITEMS'!$E$2:$G$875,2,FALSE) -> BRIDA P/INTERIOR BLANCA | G6: =VLOOKUP(E6,'LISTA ITEMS'!$E$2:$G$875,3,FALSE) -> UND | H6: 46083 | I6: 2000 | K6: 46098 | L6: 0 | M6: 46098 | N6: 0 | O6: 46098 | P6: 0 | Q6: 46098 | R6: =+I6+L6+N6-P6 -> 2000 | AC6: =+R6+W6+Y6-AA6 -> 2000 | AF6: 7 | AG6: 2 | AH6: G
A7: 4 | B7: 13 | C7: 22 | D7: 183 | E7: =CONCATENATE(B7,"-",C7,"-",D7) -> 13-22-183 | F7: =VLOOKUP(E7,'LISTA ITEMS'!$E$2:$G$875,2,FALSE) -> BRIDA P/INTERIOR NEGRA | G7: =VLOOKUP(E7,'LISTA ITEMS'!$E$2:$G$875,3,FALSE) -> UND | H7: 46083 | I7: 1900 | K7: 46098 | L7: 0 | M7: 46098 | N7: 0 | O7: 46098 | P7: 0 | Q7: 46098 | R7: =+I7+L7+N7-P7 -> 1900 | AC7: =+R7+W7+Y7-AA7 -> 1900 | AF7: 7 | AG7: 2 | AH7: G
A8: 5 | B8: 13 | C8: 22 | D8: 184 | E8: =CONCATENATE(B8,"-",C8,"-",D8) -> 13-22-184 | F8: =VLOOKUP(E8,'LISTA ITEMS'!$E$2:$G$875,2,FALSE) -> BRIDA P/EXTERIOR NEGRA | G8: =VLOOKUP(E8,'LISTA ITEMS'!$E$2:$G$875,3,FALSE) -> UND | H8: 46083 | I8: 100 | K8: 46098 | L8: 300 | M8: 46098 | N8: 0 | O8: 46098 | P8: 1450 | Q8: 46098 | R8: =+I8+L8+N8-P8 -> -1050 | AC8: =+R8+W8+Y8-AA8 -> -1050 | AF8: 7 | AG8: 1 | AH8: G
A9: 6 | B9: 13 | C9: 23 | D9: 185 | E9: =CONCATENATE(B9,"-",C9,"-",D9) -> 13-23-185 | F9: =VLOOKUP(E9,'LISTA ITEMS'!$E$2:$G$875,2,FALSE) -> CINTA BLANCA AISLANTE PVC 50MM | G9: =VLOOKUP(E9,'LISTA ITEMS'!$E$2:$G$875,3,FALSE) -> UND | H9: 46083 | I9: 1 | K9: 46098 | L9: 0 | M9: 46098 | N9: 0 | O9: 46098 | P9: 2 | Q9: 46098 | R9: =+I9+L9+N9-P9 -> -1 | AC9: =+R9+W9+Y9-AA9 -> -1 | AF9: 7 | AG9: 1 | AH9: F
A10: 7 | B10: 13 | C10: 23 | D10: 186 | E10: =CONCATENATE(B10,"-",C10,"-",D10) -> 13-23-186 | F10: =VLOOKUP(E10,'LISTA ITEMS'!$E$2:$G$875,2,FALSE) -> CINTA NEGRA AISLANTE PVC 50MM | G10: =VLOOKUP(E10,'LISTA ITEMS'!$E$2:$G$875,3,FALSE) -> UND | H10: 46083 | I10: 2 | K10: 46098 | L10: 0 | M10: 46098 | N10: 0 | O10: 46098 | P10: 0 | Q10: 46098 | R10: =+I10+L10+N10-P10 -> 2 | AC10: =+R10+W10+Y10-AA10 -> 2 | AF10: 7 | AG10: 1 | AH10: F
A11: 8 | B11: 13 | C11: 23 | D11: 187 | E11: =CONCATENATE(B11,"-",C11,"-",D11) -> 13-23-187 | F11: =VLOOKUP(E11,'LISTA ITEMS'!$E$2:$G$875,2,FALSE) -> CINTA VERDE AMARILLA AISLANTE PVC 19MM | G11: =VLOOKUP(E11,'LISTA ITEMS'!$E$2:$G$875,3,FALSE) -> UND | H11: 46083 | I11: 2 | K11: 46098 | L11: 0 | M11: 46098 | N11: 0 | O11: 46098 | P11: 2 | Q11: 46098 | R11: =+I11+L11+N11-P11 -> 0 | AC11: =+R11+W11+Y11-AA11 -> 0 | AF11: 7 | AG11: 1 | AH11: F
A12: 9 | B12: 13 | C12: 23 | D12: 188 | E12: =CONCATENATE(B12,"-",C12,"-",D12) -> 13-23-188 | F12: =VLOOKUP(E12,'LISTA ITEMS'!$E$2:$G$875,2,FALSE) -> CINTA ROJA AISLANTE PVC 19MM | G12: =VLOOKUP(E12,'LISTA ITEMS'!$E$2:$G$875,3,FALSE) -> UND | H12: 46083 | I12: 7 | K12: 46098 | L12: 0 | M12: 46098 | N12: 0 | O12: 46098 | P12: 0 | Q12: 46098 | R12: =+I12+L12+N12-P12 -> 7 | AC12: =+R12+W12+Y12-AA12 -> 7 | AF12: 7 | AG12: 1 | AH12: F
A13: 10 | B13: 13 | C13: 23 | D13: 189 | E13: =CONCATENATE(B13,"-",C13,"-",D13) -> 13-23-189 | F13: =VLOOKUP(E13,'LISTA ITEMS'!$E$2:$G$875,2,FALSE) -> CINTA AZUL AISLANTE PVC 19MM | G13: =VLOOKUP(E13,'LISTA ITEMS'!$E$2:$G$875,3,FALSE) -> UND | H13: 46083 | I13: 8 | K13: 46098 | L13: 0 | M13: 46098 | N13: 0 | O13: 46098 | P13: 0 | Q13: 46098 | R13: =+I13+L13+N13-P13 -> 8 | AC13: =+R13+W13+Y13-AA13 -> 8 | AF13: 7 | AG13: 1 | AH13: F
A14: 11 | B14: 13 | C14: 23 | D14: 190 | E14: =CONCATENATE(B14,"-",C14,"-",D14) -> 13-23-190 | F14: =VLOOKUP(E14,'LISTA ITEMS'!$E$2:$G$875,2,FALSE) -> CINTA BLANCA AISLANTE PVC 19MM | G14: =VLOOKUP(E14,'LISTA ITEMS'!$E$2:$G$875,3,FALSE) -> UND | H14: 46083 | I14: 7 | K14: 46098 | L14: 0 | M14: 46098 | N14: 0 | O14: 46098 | P14: 0 | Q14: 46098 | R14: =+I14+L14+N14-P14 -> 7 | AC14: =+R14+W14+Y14-AA14 -> 7 | AF14: 7 | AG14: 1 | AH14: F
A15: 12 | B15: 13 | C15: 23 | D15: 191 | E15: =CONCATENATE(B15,"-",C15,"-",D15) -> 13-23-191 | F15: =VLOOKUP(E15,'LISTA ITEMS'!$E$2:$G$875,2,FALSE) -> CINTA NEGRA AISLANTE PVC 19MM | G15: =VLOOKUP(E15,'LISTA ITEMS'!$E$2:$G$875,3,FALSE) -> UND | H15: 46083 | I15: 10 | K15: 46098 | L15: 0 | M15: 46098 | N15: 0 | O15: 46098 | P15: 0 | Q15: 46098 | R15: =+I15+L15+N15-P15 -> 10 | AC15: =+R15+W15+Y15-AA15 -> 10 | AF15: 7 | AG15: 1 | AH15: F
... A33: 30 | B33: 1 | C33: 27 | D33: 208 | E33: =CONCATENATE(B33,"-",C33,"-",D33) -> 1-27-208 | F33: =VLOOKUP(E33,'LISTA ITEMS'!$E$2:$G$875,2,FALSE) -> TORNILLO A/INOX CABEZA CILINDRICA ALLEN M8X30mm | G33: =VLOOKUP(E33,'LISTA ITEMS'!$E$2:$G$875,3,FALSE) -> UND | H33: 46083 | I33: 75 | K33: 46098 | L33: 0 | M33: 46098 | N33: 0 | O33: 46098 | P33: 0 | Q33: 46098 | R33: =+I33+L33+N33-P33 -> 75 | AC33: =+R33+W33+Y33-AA33 -> 75 | AF33: 7 | AG33: 1 | AH33: C
A34: 31 | B34: 3 | C34: 31 | D34: 209 | E34: =CONCATENATE(B34,"-",C34,"-",D34) -> 3-31-209 | F34: =VLOOKUP(E34,'LISTA ITEMS'!$E$2:$G$875,2,FALSE) -> CABLE Nª 6 C/ALTERNA MARRON | G34: =VLOOKUP(E34,'LISTA ITEMS'!$E$2:$G$875,3,FALSE) -> MT | H34: 46083 | I34: 230 | K34: 46098 | L34: 30 | M34: 46098 | N34: 300 | O34: 46098 | P34: 100 | Q34: 46098 | R34: =+I34+L34+N34-P34 -> 460 | S34: 46098 | T34: 300 | AC34: =+R34+W34+Y34-AA34 -> 460 | AF34: 10 | AG34: 2 | AH34: A | AI34: OK
A35: 32 | B35: 3 | C35: 31 | D35: 210 | E35: =CONCATENATE(B35,"-",C35,"-",D35) -> 3-31-210 | F35: =VLOOKUP(E35,'LISTA ITEMS'!$E$2:$G$875,2,FALSE) -> CABLE Nª 6 C/ALTERNA GRIS | G35: =VLOOKUP(E35,'LISTA ITEMS'!$E$2:$G$875,3,FALSE) -> MT | H35: 46083 | I35: 230 | K35: 46098 | L35: 30 | M35: 46098 | N35: 300 | O35: 46098 | P35: 100 | Q35: 46098 | R35: =+I35+L35+N35-P35 -> 460 | S35: 46098 | T35: 300 | AC35: =+R35+W35+Y35-AA35 -> 460 | AF35: 10 | AG35: 2 | AH35: A | AI35: OK
A36: 33 | B36: 3 | C36: 31 | D36: 211 | E36: =CONCATENATE(B36,"-",C36,"-",D36) -> 3-31-211 | F36: =VLOOKUP(E36,'LISTA ITEMS'!$E$2:$G$875,2,FALSE) -> CABLE Nª 6 C/ALTERNA VERDE/AMARILLO | G36: =VLOOKUP(E36,'LISTA ITEMS'!$E$2:$G$875,3,FALSE) -> MT | H36: 46083 | I36: 400 | K36: 46098 | L36: 30 | M36: 46098 | N36: 300 | O36: 46098 | P36: 100 | Q36: 46098 | R36: =+I36+L36+N36-P36 -> 630 | S36: 46098 | T36: 300 | AC36: =+R36+W36+Y36-AA36 -> 630 | AF36: 10 | AG36: 2 | AH36: A | AI36: OK
A37: 34 | B37: 3 | C37: 31 | D37: 212 | E37: =CONCATENATE(B37,"-",C37,"-",D37) -> 3-31-212 | F37: =VLOOKUP(E37,'LISTA ITEMS'!$E$2:$G$875,2,FALSE) -> CABLE Nª 6 C/ALTERNA AZUL | G37: =VLOOKUP(E37,'LISTA ITEMS'!$E$2:$G$875,3,FALSE) -> MT | H37: 46083 | I37: 300 | K37: 46098 | L37: 130 | M37: 46098 | N37: 300 | O37: 46098 | P37: 300 | Q37: 46098 | R37: =+I37+L37+N37-P37 -> 430 | S37: 46098 | T37: 400 | AC37: =+R37+W37+Y37-AA37 -> 430 | AF37: 10 | AG37: 2 | AH37: A | AI37: OK
A38: 35 | B38: 3 | C38: 31 | D38: 213 | E38: =CONCATENATE(B38,"-",C38,"-",D38) -> 3-31-213 | F38: =VLOOKUP(E38,'LISTA ITEMS'!$E$2:$G$875,2,FALSE) -> CABLE Nª 6 C/ALTERNA NEGRO | G38: =VLOOKUP(E38,'LISTA ITEMS'!$E$2:$G$875,3,FALSE) -> MT | H38: 46083 | I38: 400 | K38: 46098 | L38: 130 | M38: 46098 | N38: 100 | O38: 46098 | P38: 300 | Q38: 46098 | R38: =+I38+L38+N38-P38 -> 330 | S38: 46098 | T38: 200 | AC38: =+R38+W38+Y38-AA38 -> 330 | AF38: 10 | AG38: 2 | AH38: A | AI38: OK
A39: 36 | B39: 3 | C39: 31 | D39: 214 | E39: =CONCATENATE(B39,"-",C39,"-",D39) -> 3-31-214 | F39: =VLOOKUP(E39,'LISTA ITEMS'!$E$2:$G$875,2,FALSE) -> CABLE Nª 16 C/ALTERNA NEGRO | G39: =VLOOKUP(E39,'LISTA ITEMS'!$E$2:$G$875,3,FALSE) -> MT | H39: 46083 | I39: 100 | K39: 46098 | L39: 0 | M39: 46098 | N39: 0 | O39: 46098 | P39: 0 | Q39: 46098 | R39: =+I39+L39+N39-P39 -> 100 | S39: 46098 | T39: 100 | AC39: =+R39+W39+Y39-AA39 -> 100 | AF39: 10 | AG39: 2 | AH39: A | AI39: OK
A40: 37 | B40: 3 | C40: 31 | D40: 215 | E40: =CONCATENATE(B40,"-",C40,"-",D40) -> 3-31-215 | F40: =VLOOKUP(E40,'LISTA ITEMS'!$E$2:$G$875,2,FALSE) -> CABLE Nª 16 C/ALTERNA MARRON | G40: =VLOOKUP(E40,'LISTA ITEMS'!$E$2:$G$875,3,FALSE) -> MT | H40: 46083 | I40: 100 | K40: 46098 | L40: 0 | M40: 46098 | N40: 0 | O40: 46098 | P40: 0 | Q40: 46098 | R40: =+I40+L40+N40-P40 -> 100 | S40: 46098 | T40: 100 | AC40: =+R40+W40+Y40-AA40 -> 100 | AF40: 10 | AG40: 2 | AH40: A | AI40: OK
A41: 38 | B41: 3 | C41: 31 | D41: 216 | E41: =CONCATENATE(B41,"-",C41,"-",D41) -> 3-31-216 | F41: =VLOOKUP(E41,'LISTA ITEMS'!$E$2:$G$875,2,FALSE) -> CABLE Nª 16 C/ALTERNA AZUL | G41: =VLOOKUP(E41,'LISTA ITEMS'!$E$2:$G$875,3,FALSE) -> MT | H41: 46083 | I41: 100 | K41: 46098 | L41: 0 | M41: 46098 | N41: 0 | O41: 46098 | P41: 0 | Q41: 46098 | R41: =+I41+L41+N41-P41 -> 100 | S41: 46098 | T41: 100 | AC41: =+R41+W41+Y41-AA41 -> 100 | AF41: 10 | AG41: 2 | AH41: A | AI41: OK
A42: 39 | B42: 3 | C42: 31 | D42: 217 | E42: =CONCATENATE(B42,"-",C42,"-",D42) -> 3-31-217 | F42: =VLOOKUP(E42,'LISTA ITEMS'!$E$2:$G$875,2,FALSE) -> CABLE Nª 16 C/ALTERNA GRIS | G42: =VLOOKUP(E42,'LISTA ITEMS'!$E$2:$G$875,3,FALSE) -> MT | H42: 46083 | I42: 100 | K42: 46098 | L42: 0 | M42: 46098 | N42: 0 | O42: 46098 | P42: 0 | Q42: 46098 | R42: =+I42+L42+N42-P42 -> 100 | S42: 46098 | T42: 100 | AC42: =+R42+W42+Y42-AA42 -> 100 | AF42: 10 | AG42: 2 | AH42: A | AI42: OK
A43: 40 | B43: 3 | C43: 31 | D43: 218 | E43: =CONCATENATE(B43,"-",C43,"-",D43) -> 3-31-218 | F43: =VLOOKUP(E43,'LISTA ITEMS'!$E$2:$G$875,2,FALSE) -> CABLE Nª 10 C/ALTERNA VERDE/AMARILLO | G43: =VLOOKUP(E43,'LISTA ITEMS'!$E$2:$G$875,3,FALSE) -> MT | H43: 46083 | I43: 383 | K43: 46098 | L43: 0 | M43: 46098 | N43: 0 | O43: 46098 | P43: 0 | Q43: 46098 | R43: =+I43+L43+N43-P43 -> 383 | S43: 46098 | T43: 500 | AC43: =+R43+W43+Y43-AA43 -> 383 | AF43: 10 | AG43: 2 | AH43: A | AI43: OK
A44: 41 | B44: 3 | C44: 31 | D44: 219 | E44: =CONCATENATE(B44,"-",C44,"-",D44) -> 3-31-219 | F44: =VLOOKUP(E44,'LISTA ITEMS'!$E$2:$G$875,2,FALSE) -> CABLE Nª 10 C/ALTERNA MARRON | G44: =VLOOKUP(E44,'LISTA ITEMS'!$E$2:$G$875,3,FALSE) -> MT | H44: 46083 | I44: 53 | K44: 46098 | L44: 0 | M44: 46098 | N44: 100 | O44: 46098 | P44: 0 | Q44: 46098 | R44: =+I44+L44+N44-P44 -> 153 | S44: 46098 | T44: 300 | AC44: =+R44+W44+Y44-AA44 -> 153 | AF44: 10 | AG44: 2 | AH44: A | AI44: OK
A45: 42 | B45: 3 | C45: 31 | D45: 220 | E45: =CONCATENATE(B45,"-",C45,"-",D45) -> 3-31-220 | F45: =VLOOKUP(E45,'LISTA ITEMS'!$E$2:$G$875,2,FALSE) -> CABLE Nª 10 C/ALTERNA GRIS | G45: =VLOOKUP(E45,'LISTA ITEMS'!$E$2:$G$875,3,FALSE) -> MT | H45: 46083 | I45: -52 | K45: 46098 | L45: 0 | M45: 46098 | N45: 100 | O45: 46098 | P45: 0 | Q45: 46098 | R45: =+I45+L45+N45-P45 -> 48 | S45: 46098 | T45: 100 | AC45: =+R45+W45+Y45-AA45 -> 48 | AF45: 10 | AG45: 2 | AH45: A | AI45: OK
... A47: 44 | B47: 3 | C47: 31 | D47: 222 | E47: =CONCATENATE(B47,"-",C47,"-",D47) -> 3-31-222 | F47: =VLOOKUP(E47,'LISTA ITEMS'!$E$2:$G$875,2,FALSE) -> CABLE Nª 10 C/ALTERNA NEGRO | G47: =VLOOKUP(E47,'LISTA ITEMS'!$E$2:$G$875,3,FALSE) -> MT | H47: 46083 | I47: 333 | K47: 46098 | L47: 0 | M47: 46098 | N47: 100 | O47: 46098 | P47: 0 | Q47: 46098 | R47: =+I47+L47+N47-P47 -> 433 | S47: 46098 | T47: 350 | AC47: =+R47+W47+Y47-AA47 -> 433 | AF47: 10 | AG47: 2 | AH47: A | AI47: OK
A48: 45 | B48: 9 | C48: 32 | D48: 223 | E48: =CONCATENATE(B48,"-",C48,"-",D48) -> 9-32-223 | F48: =VLOOKUP(E48,'LISTA ITEMS'!$E$2:$G$875,2,FALSE) -> CURVA PVC M-25 GRIS TIPO A | G48: =VLOOKUP(E48,'LISTA ITEMS'!$E$2:$G$875,3,FALSE) -> UND | H48: 46083 | I48: 472 | K48: 46098 | L48: 36 | M48: 46098 | N48: 200 | O48: 46098 | P48: 129 | Q48: 46098 | R48: =+I48+L48+N48-P48 -> 579 | AC48: =+R48+W48+Y48-AA48 -> 579 | AF48: 10 | AG48: 1 | AH48: A
A49: 46 | B49: 9 | C49: 32 | D49: 224 | E49: =CONCATENATE(B49,"-",C49,"-",D49) -> 9-32-224 | F49: =VLOOKUP(E49,'LISTA ITEMS'!$E$2:$G$875,2,FALSE) -> CURVA PVC M-25 GRIS TIPO B | G49: =VLOOKUP(E49,'LISTA ITEMS'!$E$2:$G$875,3,FALSE) -> UND | H49: 46083 | I49: 80 | K49: 46098 | L49: 0 | M49: 46098 | N49: 0 | O49: 46098 | P49: 5 | Q49: 46098 | R49: =+I49+L49+N49-P49 -> 75 | AC49: =+R49+W49+Y49-AA49 -> 75 | AF49: 10 | AG49: 1 | AH49: A
A50: 47 | B50: 9 | C50: 32 | D50: 225 | E50: =CONCATENATE(B50,"-",C50,"-",D50) -> 9-32-225 | F50: =VLOOKUP(E50,'LISTA ITEMS'!$E$2:$G$875,2,FALSE) -> CURVA PVC M-40 GRIS | G50: =VLOOKUP(E50,'LISTA ITEMS'!$E$2:$G$875,3,FALSE) -> UND | H50: 46083 | I50: 37 | K50: 46098 | L50: 0 | M50: 46098 | N50: 0 | O50: 46098 | P50: 0 | Q50: 46098 | R50: =+I50+L50+N50-P50 -> 37 | AC50: =+R50+W50+Y50-AA50 -> 37 | AF50: 10 | AG50: 1 | AH50: A
A51: 48 | B51: 16 | C51: 33 | D51: 226 | E51: =CONCATENATE(B51,"-",C51,"-",D51) -> 16-33-226 | F51: =VLOOKUP(E51,'LISTA ITEMS'!$E$2:$G$875,2,FALSE) -> OPTIMIZADOR SUN2000P-375W | G51: =VLOOKUP(E51,'LISTA ITEMS'!$E$2:$G$875,3,FALSE) -> UND | H51: 46083 | I51: 13 | K51: 46098 | L51: 0 | M51: 46098 | N51: 0 | O51: 46098 | P51: 0 | Q51: 46098 | R51: =+I51+L51+N51-P51 -> 13 | AC51: =+R51+W51+Y51-AA51 -> 13 | AF51: 10 | AG51: 1 | AH51: A
A52: 49 | B52: 10 | C52: 34 | D52: 227 | E52: =CONCATENATE(B52,"-",C52,"-",D52) -> 10-34-227 | F52: =VLOOKUP(E52,'LISTA ITEMS'!$E$2:$G$875,2,FALSE) -> MICRORAIL 2X30 PERFORADO | G52: =VLOOKUP(E52,'LISTA ITEMS'!$E$2:$G$875,3,FALSE) -> UND | H52: 46083 | I52: 186 | K52: 46098 | L52: 0 | M52: 46098 | N52: 0 | O52: 46098 | P52: 0 | Q52: 46098 | R52: =+I52+L52+N52-P52 -> 186 | AC52: =+R52+W52+Y52-AA52 -> 186 | AF52: 10 | AG52: 1 | AH52: A
A53: 50 | B53: 10 | C53: 37 | D53: 232 | E53: =CONCATENATE(B53,"-",C53,"-",D53) -> 10-37-232 | F53: =VLOOKUP(E53,'LISTA ITEMS'!$E$2:$G$875,2,FALSE) -> SOPORTE CENTRAL NEGRO | G53: =VLOOKUP(E53,'LISTA ITEMS'!$E$2:$G$875,3,FALSE) -> UND | H53: 46083 | I53: 87 | K53: 46098 | L53: 136 | M53: 46098 | N53: 180 | O53: 46098 | P53: 660 | Q53: 46098 | R53: =+I53+L53+N53-P53 -> -257 | AC53: =+R53+W53+Y53-AA53 -> -257 | AF53: 10 | AG53: 1 | AH53: B
A54: 51 | B54: 7 | C54: 38 | D54: 233 | E54: =CONCATENATE(B54,"-",C54,"-",D54) -> 7-38-233 | F54: =VLOOKUP(E54,'LISTA ITEMS'!$E$2:$G$875,2,FALSE) -> PLACA SOLAR EX-275P-60 275W / 31.50V | G54: =VLOOKUP(E54,'LISTA ITEMS'!$E$2:$G$875,3,FALSE) -> UND | H54: 46083 | I54: 1 | K54: 46098 | L54: 0 | M54: 46098 | N54: 0 | O54: 46098 | P54: 0 | Q54: 46098 | R54: =+I54+L54+N54-P54 -> 1 | T54: 1 | AC54: =+R54+W54+Y54-AA54 -> 1 | AE54: GRIS | AF54: 5 | AG54: PARED | AH54: 3
A55: 52 | B55: 7 | C55: 38 | D55: 234 | E55: =CONCATENATE(B55,"-",C55,"-",D55) -> 7-38-234 | F55: =VLOOKUP(E55,'LISTA ITEMS'!$E$2:$G$875,2,FALSE) -> PLACA SOLAR CSP-6P-345W / 38.3C | G55: =VLOOKUP(E55,'LISTA ITEMS'!$E$2:$G$875,3,FALSE) -> UND | H55: 46083 | I55: 1 | K55: 46098 | L55: 0 | M55: 46098 | N55: 0 | O55: 46098 | P55: 0 | Q55: 46098 | R55: =+I55+L55+N55-P55 -> 1 | T55: 1 | AC55: =+R55+W55+Y55-AA55 -> 1 | AE55: GRIS | AF55: 5 | AG55: PARED | AH55: 4
A56: 53 | B56: 7 | C56: 38 | D56: 235 | E56: =CONCATENATE(B56,"-",C56,"-",D56) -> 7-38-235 | F56: =VLOOKUP(E56,'LISTA ITEMS'!$E$2:$G$875,2,FALSE) -> PLACA SOLAR CS6L-450MS 450W / 34.4V | G56: =VLOOKUP(E56,'LISTA ITEMS'!$E$2:$G$875,3,FALSE) -> UND | H56: 46083 | I56: 1 | K56: 46098 | L56: 0 | M56: 46098 | N56: 0 | O56: 46098 | P56: 0 | Q56: 46098 | R56: =+I56+L56+N56-P56 -> 1 | T56: 1 | AC56: =+R56+W56+Y56-AA56 -> 1 | AE56: NEGRA | AF56: 5 | AG56: PARED | AH56: 5
A57: 54 | B57: 7 | C57: 38 | D57: 236 | E57: =CONCATENATE(B57,"-",C57,"-",D57) -> 7-38-236 | F57: =VLOOKUP(E57,'LISTA ITEMS'!$E$2:$G$875,2,FALSE) -> PLACA SOLAR JAM66S30-505MR 505W / 45.72V | G57: =VLOOKUP(E57,'LISTA ITEMS'!$E$2:$G$875,3,FALSE) -> UND | H57: 46083 | I57: 1 | K57: 46098 | L57: 0 | M57: 46098 | N57: 0 | O57: 46098 | P57: 0 | Q57: 46098 | R57: =+I57+L57+N57-P57 -> 1 | T57: 1 | AC57: =+R57+W57+Y57-AA57 -> 1 | AE57: GRIS | AF57: 5 | AG57: PARED | AH57: 2
A58: 55 | B58: 7 | C58: 38 | D58: 237 | E58: =CONCATENATE(B58,"-",C58,"-",D58) -> 7-38-237 | F58: =VLOOKUP(E58,'LISTA ITEMS'!$E$2:$G$875,2,FALSE) -> PLACA SOLAR CS6.1-60TB-505 505W / 43.4V | G58: =VLOOKUP(E58,'LISTA ITEMS'!$E$2:$G$875,3,FALSE) -> UND | H58: 46083 | I58: 2 | K58: 46098 | L58: 0 | M58: 46098 | N58: 0 | O58: 46098 | P58: 0 | Q58: 46098 | R58: =+I58+L58+N58-P58 -> 2 | T58: 2 | AC58: =+R58+W58+Y58-AA58 -> 2 | AE58: NEGRA | AF58: 5 | AG58: PARED | AH58: 1
...

Sheet LISTA ITEMS
A1: TOMA DE INVENTARIO
A2: # | B2: GRUPO | C2: ELEMENTO | D2: ITEM | E2: CONCATENADO | F2: DESCRIPCION | G2: UND MEDIDA | H2: PROVEEDOR
A3: 1 | B3: 7 | C3: 20 | D3: 178 | E3: =CONCATENATE(B3,"-",C3,"-",D3) -> 7-20-178 | F3: =IFERROR(VLOOKUP(E3,'ESTRUCTURA CODIGO'!$H$2:$J$1048576,2,FALSE)," ") -> ESTUFA CALEFACCION 9 KW | G3: =IFERROR(VLOOKUP(E3,'ESTRUCTURA CODIGO'!$H$2:$J$1048576,3,FALSE)," ") -> UND | H3: =IFERROR(VLOOKUP(E3,'ESTRUCTURA CODIGO'!$H$2:$L$612,4,FALSE)," ") -> 0
A4: 2 | B4: 7 | C4: 20 | D4: 179 | E4: =CONCATENATE(B4,"-",C4,"-",D4) -> 7-20-179 | F4: =IFERROR(VLOOKUP(E4,'ESTRUCTURA CODIGO'!$H$2:$J$1048576,2,FALSE)," ") -> ESTUFA CALEFACCION 12 KW | G4: =IFERROR(VLOOKUP(E4,'ESTRUCTURA CODIGO'!$H$2:$J$1048576,3,FALSE)," ") -> UND | H4: =IFERROR(VLOOKUP(E4,'ESTRUCTURA CODIGO'!$H$2:$L$612,4,FALSE)," ") -> 0
A5: 3 | B5: 13 | C5: 21 | D5: 180 | E5: =CONCATENATE(B5,"-",C5,"-",D5) -> 13-21-180 | F5: =IFERROR(VLOOKUP(E5,'ESTRUCTURA CODIGO'!$H$2:$J$1048576,2,FALSE)," ") -> TACO P/BRIDA BLANCO | G5: =IFERROR(VLOOKUP(E5,'ESTRUCTURA CODIGO'!$H$2:$J$1048576,3,FALSE)," ") -> UND | H5: =IFERROR(VLOOKUP(E5,'ESTRUCTURA CODIGO'!$H$2:$L$612,4,FALSE)," ") -> RECA
A6: 4 | B6: 13 | C6: 21 | D6: 181 | E6: =CONCATENATE(B6,"-",C6,"-",D6) -> 13-21-181 | F6: =IFERROR(VLOOKUP(E6,'ESTRUCTURA CODIGO'!$H$2:$J$1048576,2,FALSE)," ") -> TACO P/BRIDA NEGRO | G6: =IFERROR(VLOOKUP(E6,'ESTRUCTURA CODIGO'!$H$2:$J$1048576,3,FALSE)," ") -> UND | H6: =IFERROR(VLOOKUP(E6,'ESTRUCTURA CODIGO'!$H$2:$L$612,4,FALSE)," ") -> RECA
A7: 5 | B7: 13 | C7: 22 | D7: 182 | E7: =CONCATENATE(B7,"-",C7,"-",D7) -> 13-22-182 | F7: =IFERROR(VLOOKUP(E7,'ESTRUCTURA CODIGO'!$H$2:$J$1048576,2,FALSE)," ") -> BRIDA P/INTERIOR BLANCA | G7: =IFERROR(VLOOKUP(E7,'ESTRUCTURA CODIGO'!$H$2:$J$1048576,3,FALSE)," ") -> UND | H7: =IFERROR(VLOOKUP(E7,'ESTRUCTURA CODIGO'!$H$2:$L$612,4,FALSE)," ") -> RECA
A8: 6 | B8: 13 | C8: 22 | D8: 183 | E8: =CONCATENATE(B8,"-",C8,"-",D8) -> 13-22-183 | F8: =IFERROR(VLOOKUP(E8,'ESTRUCTURA CODIGO'!$H$2:$J$1048576,2,FALSE)," ") -> BRIDA P/INTERIOR NEGRA | G8: =IFERROR(VLOOKUP(E8,'ESTRUCTURA CODIGO'!$H$2:$J$1048576,3,FALSE)," ") -> UND | H8: =IFERROR(VLOOKUP(E8,'ESTRUCTURA CODIGO'!$H$2:$L$612,4,FALSE)," ") -> RECA
A9: 7 | B9: 13 | C9: 22 | D9: 184 | E9: =CONCATENATE(B9,"-",C9,"-",D9) -> 13-22-184 | F9: =IFERROR(VLOOKUP(E9,'ESTRUCTURA CODIGO'!$H$2:$J$1048576,2,FALSE)," ") -> BRIDA P/EXTERIOR NEGRA | G9: =IFERROR(VLOOKUP(E9,'ESTRUCTURA CODIGO'!$H$2:$J$1048576,3,FALSE)," ") -> UND | H9: =IFERROR(VLOOKUP(E9,'ESTRUCTURA CODIGO'!$H$2:$L$612,4,FALSE)," ") -> RECA
A10: 8 | B10: 13 | C10: 23 | D10: 185 | E10: =CONCATENATE(B10,"-",C10,"-",D10) -> 13-23-185 | F10: =IFERROR(VLOOKUP(E10,'ESTRUCTURA CODIGO'!$H$2:$J$1048576,2,FALSE)," ") -> CINTA BLANCA AISLANTE PVC 50MM | G10: =IFERROR(VLOOKUP(E10,'ESTRUCTURA CODIGO'!$H$2:$J$1048576,3,FALSE)," ") -> UND | H10: =IFERROR(VLOOKUP(E10,'ESTRUCTURA CODIGO'!$H$2:$L$612,4,FALSE)," ") -> RECA
A11: 9 | B11: 13 | C11: 23 | D11: 186 | E11: =CONCATENATE(B11,"-",C11,"-",D11) -> 13-23-186 | F11: =IFERROR(VLOOKUP(E11,'ESTRUCTURA CODIGO'!$H$2:$J$1048576,2,FALSE)," ") -> CINTA NEGRA AISLANTE PVC 50MM | G11: =IFERROR(VLOOKUP(E11,'ESTRUCTURA CODIGO'!$H$2:$J$1048576,3,FALSE)," ") -> UND | H11: =IFERROR(VLOOKUP(E11,'ESTRUCTURA CODIGO'!$H$2:$L$612,4,FALSE)," ") -> RECA
A12: 10 | B12: 13 | C12: 23 | D12: 187 | E12: =CONCATENATE(B12,"-",C12,"-",D12) -> 13-23-187 | F12: =IFERROR(VLOOKUP(E12,'ESTRUCTURA CODIGO'!$H$2:$J$1048576,2,FALSE)," ") -> CINTA VERDE AMARILLA AISLANTE PVC 19MM | G12: =IFERROR(VLOOKUP(E12,'ESTRUCTURA CODIGO'!$H$2:$J$1048576,3,FALSE)," ") -> UND | H12: =IFERROR(VLOOKUP(E12,'ESTRUCTURA CODIGO'!$H$2:$L$612,4,FALSE)," ") -> RECA
A13: 11 | B13: 13 | C13: 23 | D13: 188 | E13: =CONCATENATE(B13,"-",C13,"-",D13) -> 13-23-188 | F13: =IFERROR(VLOOKUP(E13,'ESTRUCTURA CODIGO'!$H$2:$J$1048576,2,FALSE)," ") -> CINTA ROJA AISLANTE PVC 19MM | G13: =IFERROR(VLOOKUP(E13,'ESTRUCTURA CODIGO'!$H$2:$J$1048576,3,FALSE)," ") -> UND | H13: =IFERROR(VLOOKUP(E13,'ESTRUCTURA CODIGO'!$H$2:$L$612,4,FALSE)," ") -> RECA
A14: 12 | B14: 13 | C14: 23 | D14: 189 | E14: =CONCATENATE(B14,"-",C14,"-",D14) -> 13-23-189 | F14: =IFERROR(VLOOKUP(E14,'ESTRUCTURA CODIGO'!$H$2:$J$1048576,2,FALSE)," ") -> CINTA AZUL AISLANTE PVC 19MM | G14: =IFERROR(VLOOKUP(E14,'ESTRUCTURA CODIGO'!$H$2:$J$1048576,3,FALSE)," ") -> UND | H14: =IFERROR(VLOOKUP(E14,'ESTRUCTURA CODIGO'!$H$2:$L$612,4,FALSE)," ") -> RECA
... A99: 97 | B99: 17 | C99: 44 | D99: 273 | E99: =CONCATENATE(B99,"-",C99,"-",D99) -> 17-44-273 | F99: =IFERROR(VLOOKUP(E99,'ESTRUCTURA CODIGO'!$H$2:$J$1048576,2,FALSE)," ") -> SELLANTE QUIMICO TACO | G99: =IFERROR(VLOOKUP(E99,'ESTRUCTURA CODIGO'!$H$2:$J$1048576,3,FALSE)," ") -> UND | H99: =IFERROR(VLOOKUP(E99,'ESTRUCTURA CODIGO'!$H$2:$L$612,4,FALSE)," ") -> RECA
A100: 98 | B100: 7 | C100: 35 | D100: 274 | E100: =CONCATENATE(B100,"-",C100,"-",D100) -> 7-35-274 | F100: =IFERROR(VLOOKUP(E100,'ESTRUCTURA CODIGO'!$H$2:$J$1048576,2,FALSE)," ") -> INVERSOR HIBRIDO MONOFASICO SPE 10000ES 10KW BATER. BAJO VOLTAJE Y BACKUP INCORP. (GROWATT) | G100: UND | H100: =IFERROR(VLOOKUP(E100,'ESTRUCTURA CODIGO'!$H$2:$L$612,4,FALSE)," ") -> COTO
A101: 99 | B101: 16 | C101: 45 | D101: 275 | E101: =CONCATENATE(B101,"-",C101,"-",D101) -> 16-45-275 | F101: =IFERROR(VLOOKUP(E101,'ESTRUCTURA CODIGO'!$H$2:$J$1048576,2,FALSE)," ") -> CAJA DISTRIBUCION INTERIOR 18 ELEM. (SOLERA) | G101: =IFERROR(VLOOKUP(E101,'ESTRUCTURA CODIGO'!$H$2:$J$1048576,3,FALSE)," ") -> UND | H101: =IFERROR(VLOOKUP(E101,'ESTRUCTURA CODIGO'!$H$2:$L$612,4,FALSE)," ") -> BELTRAN Y CRIADO
A102: 100 | B102: 16 | C102: 45 | D102: 276 | E102: =CONCATENATE(B102,"-",C102,"-",D102) -> 16-45-276 | F102: =IFERROR(VLOOKUP(E102,'ESTRUCTURA CODIGO'!$H$2:$J$1048576,2,FALSE)," ") -> CAJA ESTANCA (COCHERA) EXTERIOR 18PT (IDE) | G102: =IFERROR(VLOOKUP(E102,'ESTRUCTURA CODIGO'!$H$2:$J$1048576,3,FALSE)," ") -> UND | H102: =IFERROR(VLOOKUP(E102,'ESTRUCTURA CODIGO'!$H$2:$L$612,4,FALSE)," ") -> BELTRAN Y CRIADO
A103: 101 | B103: 3 | C103: 31 | D103: 277 | E103: =CONCATENATE(B103,"-",C103,"-",D103) -> 3-31-277 | F103: =IFERROR(VLOOKUP(E103,'ESTRUCTURA CODIGO'!$H$2:$J$1048576,2,FALSE)," ") -> CABLE Nª 6 P/PLACA SOLAR NEGRO | G103: =IFERROR(VLOOKUP(E103,'ESTRUCTURA CODIGO'!$H$2:$J$1048576,3,FALSE)," ") -> MT | H103: =IFERROR(VLOOKUP(E103,'ESTRUCTURA CODIGO'!$H$2:$L$612,4,FALSE)," ") -> COTO
A104: 102 | B104: 3 | C104: 31 | D104: 278 | E104: =CONCATENATE(B104,"-",C104,"-",D104) -> 3-31-278 | F104: =IFERROR(VLOOKUP(E104,'ESTRUCTURA CODIGO'!$H$2:$J$1048576,2,FALSE)," ") -> CABLE Nª 6 P/PLACA SOLAR ROJO | G104: =IFERROR(VLOOKUP(E104,'ESTRUCTURA CODIGO'!$H$2:$J$1048576,3,FALSE)," ") -> MT | H104: =IFERROR(VLOOKUP(E104,'ESTRUCTURA CODIGO'!$H$2:$L$612,4,FALSE)," ") -> COTO
A105: 103 | B105: 16 | C105: 46 | D105: 279 | E105: =CONCATENATE(B105,"-",C105,"-",D105) -> 16-46-279 | F105: =IFERROR(VLOOKUP(E105,'ESTRUCTURA CODIGO'!$H$2:$J$1048576,2,FALSE)," ") -> MANGUERA CORRUGADA 25mm NEGRA | G105: =IFERROR(VLOOKUP(E105,'ESTRUCTURA CODIGO'!$H$2:$J$1048576,3,FALSE)," ") -> MT | H105: =IFERROR(VLOOKUP(E105,'ESTRUCTURA CODIGO'!$H$2:$L$612,4,FALSE)," ") -> 0
A106: 104 | B106: 16 | C106: 47 | D106: 280 | E106: =CONCATENATE(B106,"-",C106,"-",D106) -> 16-47-280 | F106: =IFERROR(VLOOKUP(E106,'ESTRUCTURA CODIGO'!$H$2:$J$1048576,2,FALSE)," ") -> DIFERENCIAL EPR2A063030 2P-63A-30mA (MAXGE) | G106: =IFERROR(VLOOKUP(E106,'ESTRUCTURA CODIGO'!$H$2:$J$1048576,3,FALSE)," ") -> UND | H106: =IFERROR(VLOOKUP(E106,'ESTRUCTURA CODIGO'!$H$2:$L$612,4,FALSE)," ") -> BELTRAN Y CRIADO
A107: 105 | B107: 16 | C107: 48 | D107: 281 | E107: =CONCATENATE(B107,"-",C107,"-",D107) -> 16-48-281 | F107: =IFERROR(VLOOKUP(E107,'ESTRUCTURA CODIGO'!$H$2:$J$1048576,2,FALSE)," ") -> PORTA FUSIBLE SGF-32-DC (MAXGE) | G107: =IFERROR(VLOOKUP(E107,'ESTRUCTURA CODIGO'!$H$2:$J$1048576,3,FALSE)," ") -> UND | H107: =IFERROR(VLOOKUP(E107,'ESTRUCTURA CODIGO'!$H$2:$L$612,4,FALSE)," ") -> BELTRAN Y CRIADO
A108: 106 | B108: 16 | C108: 49 | D108: 282 | E108: =CONCATENATE(B108,"-",C108,"-",D108) -> 16-49-282 | F108: =IFERROR(VLOOKUP(E108,'ESTRUCTURA CODIGO'!$H$2:$J$1048576,2,FALSE)," ") -> CONTACTOR MODULAR RV32 (REVALCO) | G108: =IFERROR(VLOOKUP(E108,'ESTRUCTURA CODIGO'!$H$2:$J$1048576,3,FALSE)," ") -> UND | H108: =IFERROR(VLOOKUP(E108,'ESTRUCTURA CODIGO'!$H$2:$L$612,4,FALSE)," ") -> INVERSOLAR
A109: 107 | B109: 16 | C109: 50 | D109: 283 | E109: =CONCATENATE(B109,"-",C109,"-",D109) -> 16-50-283 | F109: =IFERROR(VLOOKUP(E109,'ESTRUCTURA CODIGO'!$H$2:$J$1048576,2,FALSE)," ") -> FUSIBLE 32A-1000VDC (SASSIN) | G109: =IFERROR(VLOOKUP(E109,'ESTRUCTURA CODIGO'!$H$2:$J$1048576,3,FALSE)," ") -> UND | H109: =IFERROR(VLOOKUP(E109,'ESTRUCTURA CODIGO'!$H$2:$L$612,4,FALSE)," ") -> BELTRAN Y CRIADO
A110: 108 | B110: 16 | C110: 51 | D110: 284 | E110: =CONCATENATE(B110,"-",C110,"-",D110) -> 16-51-284 | F110: =IFERROR(VLOOKUP(E110,'ESTRUCTURA CODIGO'!$H$2:$J$1048576,2,FALSE)," ") -> LIMITADOR/SOBRETENSIONES MONOFASICO 3SUR1 15/30kA-275V (SASSIN) | G110: =IFERROR(VLOOKUP(E110,'ESTRUCTURA CODIGO'!$H$2:$J$1048576,3,FALSE)," ") -> UND | H110: =IFERROR(VLOOKUP(E110,'ESTRUCTURA CODIGO'!$H$2:$L$612,4,FALSE)," ") -> BELTRAN Y CRIADO
A111: 109 | B111: 16 | C111: 52 | D111: 285 | E111: =CONCATENATE(B111,"-",C111,"-",D111) -> 16-52-285 | F111: =IFERROR(VLOOKUP(E111,'ESTRUCTURA CODIGO'!$H$2:$J$1048576,2,FALSE)," ") -> TERMICO EPBE63M1NC63 1P+N C63 (MAXGE) | G111: =IFERROR(VLOOKUP(E111,'ESTRUCTURA CODIGO'!$H$2:$J$1048576,3,FALSE)," ") -> UND | H111: =IFERROR(VLOOKUP(E111,'ESTRUCTURA CODIGO'!$H$2:$L$612,4,FALSE)," ") -> BELTRAN Y CRIADO
A112: 110 | B112: 7 | C112: 35 | D112: 286 | E112: =CONCATENATE(B112,"-",C112,"-",D112) -> 7-35-286 | F112: =IFERROR(VLOOKUP(E112,'ESTRUCTURA CODIGO'!$H$2:$J$1048576,2,FALSE)," ") -> INVERSOR SPH 6000TL BL-UP 6KW (GROWATT) | G112: =IFERROR(VLOOKUP(E112,'ESTRUCTURA CODIGO'!$H$2:$J$1048576,3,FALSE)," ") -> UND | H112: =IFERROR(VLOOKUP(E112,'ESTRUCTURA CODIGO'!$H$2:$L$612,4,FALSE)," ") -> INVERSOLAR
A113: 111 | B113: 10 | C113: 37 | D113: 287 | E113: =CONCATENATE(B113,"-",C113,"-",D113) -> 10-37-287 | F113: =IFERROR(VLOOKUP(E113,'ESTRUCTURA CODIGO'!$H$2:$J$1048576,2,FALSE)," ") -> SOPORTE CENTRAL GRIS | G113: =IFERROR(VLOOKUP(E113,'ESTRUCTURA CODIGO'!$H$2:$J$1048576,3,FALSE)," ") -> UND | H113: =IFERROR(VLOOKUP(E113,'ESTRUCTURA CODIGO'!$H$2:$L$612,4,FALSE)," ") -> ESTRUSUR SOLAR
A114: 112 | B114: 16 | C114: 49 | D114: 288 | E114: 16-49-288 | F114: =IFERROR(VLOOKUP(E114,'ESTRUCTURA CODIGO'!$H$2:$J$1048576,2,FALSE)," ") -> CONTACTOR MODULAR EPC1-6322-P7 (MAXGE) | G114: =IFERROR(VLOOKUP(E114,'ESTRUCTURA CODIGO'!$H$2:$J$1048576,3,FALSE)," ") -> UND | H114: =IFERROR(VLOOKUP(E114,'ESTRUCTURA CODIGO'!$H$2:$L$612,4,FALSE)," ") -> BELTRAN Y CRIADO
A115: 113 | B115: 16 | C115: 53 | D115: 289 | E115: 16-53-289 | F115: =IFERROR(VLOOKUP(E115,'ESTRUCTURA CODIGO'!$H$2:$J$1048576,2,FALSE)," ") -> PINCHO DE COMUNICACIÓN WIFI SHINEWILAN X (GROWATT) | G115: =IFERROR(VLOOKUP(E115,'ESTRUCTURA CODIGO'!$H$2:$J$1048576,3,FALSE)," ") -> UND | H115: =IFERROR(VLOOKUP(E115,'ESTRUCTURA CODIGO'!$H$2:$L$612,4,FALSE)," ") -> BELTRAN Y CRIADO
A116: 114 | B116: 16 | C116: 53 | D116: 290 | E116: =CONCATENATE(B116,"-",C116,"-",D116) -> 16-53-290 | F116: =IFERROR(VLOOKUP(E116,'ESTRUCTURA CODIGO'!$H$2:$J$1048576,2,FALSE)," ") -> PINCHO DE COMUNICACIÓN WIFI SHINEWILAN X2 (GROWATT) | G116: =IFERROR(VLOOKUP(E116,'ESTRUCTURA CODIGO'!$H$2:$J$1048576,3,FALSE)," ") -> UND | H116: =IFERROR(VLOOKUP(E116,'ESTRUCTURA CODIGO'!$H$2:$L$612,4,FALSE)," ") -> BELTRAN Y CRIADO
A117: 115 | B117: 9 | C117: 2 | D117: 291 | E117: =CONCATENATE(B117,"-",C117,"-",D117) -> 9-2-291 | F117: =IFERROR(VLOOKUP(E117,'ESTRUCTURA CODIGO'!$H$2:$J$1048576,2,FALSE)," ") -> TUBO ELECTRICO PVC 25mm - 3mt(AISCAN) | G117: =IFERROR(VLOOKUP(E117,'ESTRUCTURA CODIGO'!$H$2:$J$1048576,3,FALSE)," ") -> UND | H117: =IFERROR(VLOOKUP(E117,'ESTRUCTURA CODIGO'!$H$2:$L$612,4,FALSE)," ") -> BELTRAN Y CRIADO
A118: 116 | B118: 16 | C118: 52 | D118: 292 | E118: =CONCATENATE(B118,"-",C118,"-",D118) -> 16-52-292 | F118: =IFERROR(VLOOKUP(E118,'ESTRUCTURA CODIGO'!$H$2:$J$1048576,2,FALSE)," ") -> TERMICO EPBE63M1NC63M1NC40 1P+N C40 (MAXGE) | G118: =IFERROR(VLOOKUP(E118,'ESTRUCTURA CODIGO'!$H$2:$J$1048576,3,FALSE)," ") -> UND | H118: =IFERROR(VLOOKUP(E118,'ESTRUCTURA CODIGO'!$H$2:$L$612,4,FALSE)," ") -> BELTRAN Y CRIADO
A119: 117 | B119: 16 | C119: 52 | D119: 293 | E119: =CONCATENATE(B119,"-",C119,"-",D119) -> 16-52-293 | F119: =IFERROR(VLOOKUP(E119,'ESTRUCTURA CODIGO'!$H$2:$J$1048576,2,FALSE)," ") -> TERMICO EPBE63M1NC63M1NC32 1P+N C32 (MAXGE) | G119: =IFERROR(VLOOKUP(E119,'ESTRUCTURA CODIGO'!$H$2:$J$1048576,3,FALSE)," ") -> UND | H119: =IFERROR(VLOOKUP(E119,'ESTRUCTURA CODIGO'!$H$2:$L$612,4,FALSE)," ") -> BELTRAN Y CRIADO
A120: 118 | B120: 16 | C120: 45 | D120: 294 | E120: =CONCATENATE(B120,"-",C120,"-",D120) -> 16-45-294 | F120: =IFERROR(VLOOKUP(E120,'ESTRUCTURA CODIGO'!$H$2:$J$1048576,2,FALSE)," ") -> CAJA DE ESTANCA 133X180X80 EV161 (IDE) | G120: =IFERROR(VLOOKUP(E120,'ESTRUCTURA CODIGO'!$H$2:$J$1048576,3,FALSE)," ") -> UND | H120: =IFERROR(VLOOKUP(E120,'ESTRUCTURA CODIGO'!$H$2:$L$612,4,FALSE)," ") -> BELTRAN Y CRIADO
A121: 119 | B121: 7 | C121: 54 | D121: 295 | E121: =CONCATENATE(B121,"-",C121,"-",D121) -> 7-54-295 | F121: =IFERROR(VLOOKUP(E121,'ESTRUCTURA CODIGO'!$H$2:$J$1048576,2,FALSE)," ") -> BATERIA LFP LITHIUM DL5.OC (DYNESS) | G121: =IFERROR(VLOOKUP(E121,'ESTRUCTURA CODIGO'!$H$2:$J$1048576,3,FALSE)," ") -> UND | H121: =IFERROR(VLOOKUP(E121,'ESTRUCTURA CODIGO'!$H$2:$L$612,4,FALSE)," ") -> INVERSOLAR
A122: 120 | B122: 7 | C122: 35 | D122: 296 | E122: =CONCATENATE(B122,"-",C122,"-",D122) -> 7-35-296 | F122: =IFERROR(VLOOKUP(E122,'ESTRUCTURA CODIGO'!$H$2:$J$1048576,2,FALSE)," ") -> INVERSOR HIBRIDO MONOFASICO SUN 12KW AM3 (DEYE) | G122: =IFERROR(VLOOKUP(E122,'ESTRUCTURA CODIGO'!$H$2:$J$1048576,3,FALSE)," ") -> UND | H122: =IFERROR(VLOOKUP(E122,'ESTRUCTURA CODIGO'!$H$2:$L$612,4,FALSE)," ") -> BELTRAN Y CRIADO
A123: 121 | B123: 16 | C123: 55 | D123: 297 | E123: =CONCATENATE(B123,"-",C123,"-",D123) -> 16-55-297 | F123: =IFERROR(VLOOKUP(E123,'ESTRUCTURA CODIGO'!$H$2:$J$1048576,2,FALSE)," ") -> MEDIDOR ENERGIA DE CARRIL MODBUS SDM230V MONOFASICO (EASTRON) | G123: =IFERROR(VLOOKUP(E123,'ESTRUCTURA CODIGO'!$H$2:$J$1048576,3,FALSE)," ") -> UND | H123: =IFERROR(VLOOKUP(E123,'ESTRUCTURA CODIGO'!$H$2:$L$612,4,FALSE)," ") -> BELTRAN Y CRIADO
A124: 122 | B124: 16 | C124: 35 | D124: 298 | E124: =CONCATENATE(B124,"-",C124,"-",D124) -> 16-35-298 | F124: =IFERROR(VLOOKUP(E124,'ESTRUCTURA CODIGO'!$H$2:$J$1048576,2,FALSE)," ") -> INVERSOR HIBRIDO TRIFASICO 10KW WIT10K HU C/BACKUP INCORPORADO Y DISEÑADO PARA BATERIA DE BAJO VOLTAJE (GROTWATT) | G124: =IFERROR(VLOOKUP(E124,'ESTRUCTURA CODIGO'!$H$2:$J$1048576,3,FALSE)," ") -> UND | H124: =IFERROR(VLOOKUP(E124,'ESTRUCTURA CODIGO'!$H$2:$L$612,4,FALSE)," ") -> COTO
...

Sheet ESTRUCTURA CODIGO
A1: LINEA | B1: GRUPO | C1: ELEMENTO | D1: ITEM | E1: G | F1: E | G1: I | H1: CONCATENAR | I1: DESCRIPCION | J1: UND MEDIDA | K1: PROVEEDOR PRIMARIO | L1: PROVEEDOR SECUNDARIO
A2: 1 | B2: ACERO INOXIDABLE | C2: CODO | G2: 1 | H2: =CONCATENATE(E2,"-",F2,"-",G2) -> --1
A3: 2 | B3: CAUCHO | C3: TUBO | G3: 2 | H3: =CONCATENATE(E3,"-",F3,"-",G3) -> --2
A4: 3 | B4: HILO | C4: TE | G4: 3 | H4: =CONCATENATE(E4,"-",F4,"-",G4) -> --3
A5: 4 | B5: GALVANIZADO | C5: ABRAZADERA | G5: 4 | H5: =CONCATENATE(E5,"-",F5,"-",G5) -> --4
A6: 5 | B6: COBRE | C6: SOMBRERETE | G6: 5 | H6: =CONCATENATE(E6,"-",F6,"-",G6) -> --5
A7: 6 | B7: ACERO | C7: DEFLECTOR | G7: 6 | H7: =CONCATENATE(E7,"-",F7,"-",G7) -> --6
A8: 7 | B8: EQUIPOS | C8: COLECTOR | G8: 7 | H8: =CONCATENATE(E8,"-",F8,"-",G8) -> --7
A9: 8 | B9: ACERO GALVALIZADO | C9: ROSETON | G9: 8 | H9: =CONCATENATE(E9,"-",F9,"-",G9) -> --8
A10: 9 | B10: PVC | C10: TERMINAL ANTILLUVIA | G10: 9 | H10: =CONCATENATE(E10,"-",F10,"-",G10) -> --9
A11: 10 | B11: ALUMINIO | C11: VALVULA | G11: 10 | H11: =CONCATENATE(E11,"-",F11,"-",G11) -> --10
A12: 11 | B12: HIERRO | C12: REDUCCION | G12: 11 | H12: =CONCATENATE(E12,"-",F12,"-",G12) -> --11
A13: 12 | B13: PLACA SOLAR | C13: EMBELLECEDOR | G13: 12 | H13: =CONCATENATE(E13,"-",F13,"-",G13) -> --12
... A22: 21 | B22: ASEO | C22: TACO BRIDA | G22: 21 | H22: =CONCATENATE(E22,"-",F22,"-",G22) -> --21
A23: 22 | C23: BRIDA | G23: 22 | H23: =CONCATENATE(E23,"-",F23,"-",G23) -> --22
A24: 23 | C24: CINTA | G24: 23 | H24: =CONCATENATE(E24,"-",F24,"-",G24) -> --23
A25: 24 | C25: DISCO | G25: 24 | H25: =CONCATENATE(E25,"-",F25,"-",G25) -> --24
A26: 25 | C26: ANCLAJE | G26: 25 | H26: =CONCATENATE(E26,"-",F26,"-",G26) -> --25
A27: 26 | C27: ESTACION DE CARGA | G27: 26 | H27: =CONCATENATE(E27,"-",F27,"-",G27) -> --26
A28: 27 | C28: TORNILLO | G28: 27 | H28: =CONCATENATE(E28,"-",F28,"-",G28) -> --27
A29: 28 | C29: ARANDELA | G29: 28 | H29: =CONCATENATE(E29,"-",F29,"-",G29) -> --28
A30: 29 | C30: ARGOLLA | G30: 29 | H30: =CONCATENATE(E30,"-",F30,"-",G30) -> --29
A31: 30 | C31: PERRILLO | G31: 30 | H31: =CONCATENATE(E31,"-",F31,"-",G31) -> --30
A32: 31 | C32: CABLE | G32: 31 | H32: =CONCATENATE(E32,"-",F32,"-",G32) -> --31
A33: 32 | C33: CURVA | G33: 32 | H33: =CONCATENATE(E33,"-",F33,"-",G33) -> --32
A34: 33 | C34: OPTIMIZADOR | G34: 33 | H34: =CONCATENATE(E34,"-",F34,"-",G34) -> --33
... A88: 87 | C88: MODULO DISTRIBUCION | G88: 87 | H88: =CONCATENATE(E88,"-",F88,"-",G88) -> --87
A89: 88 | G89: 88 | H89: =CONCATENATE(E89,"-",F89,"-",G89) -> --88
A90: 89 | G90: 89 | H90: =CONCATENATE(E90,"-",F90,"-",G90) -> --89
A91: 90 | G91: 90 | H91: =CONCATENATE(E91,"-",F91,"-",G91) -> --90
A92: 91 | G92: 91 | H92: =CONCATENATE(E92,"-",F92,"-",G92) -> --91
A93: 92 | G93: 92 | H93: =CONCATENATE(E93,"-",F93,"-",G93) -> --92
A94: 93 | G94: 93 | H94: =CONCATENATE(E94,"-",F94,"-",G94) -> --93
A95: 94 | G95: 94 | H95: =CONCATENATE(E95,"-",F95,"-",G95) -> --94
A96: 95 | G96: 95 | H96: =CONCATENATE(E96,"-",F96,"-",G96) -> --95
A97: 96 | G97: 96 | H97: =CONCATENATE(E97,"-",F97,"-",G97) -> --96
A98: 97 | G98: 97 | H98: =CONCATENATE(E98,"-",F98,"-",G98) -> --97
A99: 98 | G99: 98 | H99: =CONCATENATE(E99,"-",F99,"-",G99) -> --98
A100: 99 | G100: 99 | H100: =CONCATENATE(E100,"-",F100,"-",G100) -> --99
... A178: 177 | G178: 177 | H178: =CONCATENATE(E178,"-",F178,"-",G178) -> --177
...

Sheet OTRO
K1: CORTE DEL 01 AL 15 MARZO | V1: CORTE DEL 16 AL 31 MARZO
A2: FMT-01-INV | D2: RELACION TOMA DE INVENTARIOS DIARIOS | H2: INVENTARIO INICIAL | K2: ENTRADA DEVOLUCION | M2: ENTRADA ALBARAN | O2: SALIDA | Q2: SALDO FINAL | S2: TOMA INVENTARIO | V2: ENTRADA DEVOLUCION | X2: ENTRADA ALBARAN | Z2: SALIDA | AB2: SALDO FINAL | AF2: UBICACIÓN
A3: LINEA | B3: GRUPO | C3: ELEMENTO | D3: ITEM | E3: CONCATENADO | F3: DESCRIPCION | G3: UND MEDIDA | H3: FECHA | I3: CANTIDAD | K3: FECHA RELACION | L3: CANT. | M3: FECHA RELACION | N3: CANT. | O3: FECHA RELACION | P3: CANT. | Q3: FECHA | R3: CANTIDAD | S3: FECHA | T3: CANTIDAD | V3: FECHA RELACION | W3: CANT. | X3: FECHA RELACION | Y3: CANT. | Z3: FECHA RELACION | AA3: CANT. | AB3: FECHA | AC3: CANTIDAD | AD3: SERIAL Nª | AE3: NOTA | AF3: ZONA | AG3: ESTAN | AH3: NIVEL
A4: 242 | E4: =CONCATENATE(B4,"-",C4,"-",D4) -> -- | F4: =VLOOKUP(E4,'LISTA ITEMS'!$E$2:$G$875,2,FALSE) -> 0 | G4: =VLOOKUP(E4,'LISTA ITEMS'!$E$2:$G$875,3,FALSE) -> 0 | I4: 0 | R4: =+I4+L4+N4-P4 -> 0 | AC4: =+R4+W4+Y4-AA4 -> 0
A5: 243 | E5: =CONCATENATE(B5,"-",C5,"-",D5) -> -- | F5: =VLOOKUP(E5,'LISTA ITEMS'!$E$2:$G$875,2,FALSE) -> 0 | G5: =VLOOKUP(E5,'LISTA ITEMS'!$E$2:$G$875,3,FALSE) -> 0 | I5: 0 | R5: =+I5+L5+N5-P5 -> 0 | AC5: =+R5+W5+Y5-AA5 -> 0
A6: 244 | E6: =CONCATENATE(B6,"-",C6,"-",D6) -> -- | F6: =VLOOKUP(E6,'LISTA ITEMS'!$E$2:$G$875,2,FALSE) -> 0 | G6: =VLOOKUP(E6,'LISTA ITEMS'!$E$2:$G$875,3,FALSE) -> 0 | I6: 0 | R6: =+I6+L6+N6-P6 -> 0 | AC6: =+R6+W6+Y6-AA6 -> 0
A7: 245 | E7: =CONCATENATE(B7,"-",C7,"-",D7) -> -- | F7: =VLOOKUP(E7,'LISTA ITEMS'!$E$2:$G$875,2,FALSE) -> 0 | G7: =VLOOKUP(E7,'LISTA ITEMS'!$E$2:$G$875,3,FALSE) -> 0 | I7: 0 | R7: =+I7+L7+N7-P7 -> 0 | AC7: =+R7+W7+Y7-AA7 -> 0
A8: 246 | E8: =CONCATENATE(B8,"-",C8,"-",D8) -> -- | F8: =VLOOKUP(E8,'LISTA ITEMS'!$E$2:$G$875,2,FALSE) -> 0 | G8: =VLOOKUP(E8,'LISTA ITEMS'!$E$2:$G$875,3,FALSE) -> 0 | I8: 0 | R8: =+I8+L8+N8-P8 -> 0 | AC8: =+R8+W8+Y8-AA8 -> 0
A9: 247 | E9: =CONCATENATE(B9,"-",C9,"-",D9) -> -- | F9: =VLOOKUP(E9,'LISTA ITEMS'!$E$2:$G$875,2,FALSE) -> 0 | G9: =VLOOKUP(E9,'LISTA ITEMS'!$E$2:$G$875,3,FALSE) -> 0 | I9: 0 | R9: =+I9+L9+N9-P9 -> 0 | AC9: =+R9+W9+Y9-AA9 -> 0
A10: 248 | E10: =CONCATENATE(B10,"-",C10,"-",D10) -> -- | F10: =VLOOKUP(E10,'LISTA ITEMS'!$E$2:$G$875,2,FALSE) -> 0 | G10: =VLOOKUP(E10,'LISTA ITEMS'!$E$2:$G$875,3,FALSE) -> 0 | I10: 0 | R10: =+I10+L10+N10-P10 -> 0 | AC10: =+R10+W10+Y10-AA10 -> 0
A11: 249 | E11: =CONCATENATE(B11,"-",C11,"-",D11) -> -- | F11: =VLOOKUP(E11,'LISTA ITEMS'!$E$2:$G$875,2,FALSE) -> 0 | G11: =VLOOKUP(E11,'LISTA ITEMS'!$E$2:$G$875,3,FALSE) -> 0 | I11: 0 | R11: =+I11+L11+N11-P11 -> 0 | AC11: =+R11+W11+Y11-AA11 -> 0
A12: 250 | E12: =CONCATENATE(B12,"-",C12,"-",D12) -> -- | F12: =VLOOKUP(E12,'LISTA ITEMS'!$E$2:$G$875,2,FALSE) -> 0 | G12: =VLOOKUP(E12,'LISTA ITEMS'!$E$2:$G$875,3,FALSE) -> 0 | I12: 0 | R12: =+I12+L12+N12-P12 -> 0 | AC12: =+R12+W12+Y12-AA12 -> 0
A13: 251 | E13: =CONCATENATE(B13,"-",C13,"-",D13) -> -- | F13: =VLOOKUP(E13,'LISTA ITEMS'!$E$2:$G$875,2,FALSE) -> 0 | G13: =VLOOKUP(E13,'LISTA ITEMS'!$E$2:$G$875,3,FALSE) -> 0 | I13: 0 | R13: =+I13+L13+N13-P13 -> 0 | AC13: =+R13+W13+Y13-AA13 -> 0
A14: 252 | E14: =CONCATENATE(B14,"-",C14,"-",D14) -> -- | F14: =VLOOKUP(E14,'LISTA ITEMS'!$E$2:$G$875,2,FALSE) -> 0 | G14: =VLOOKUP(E14,'LISTA ITEMS'!$E$2:$G$875,3,FALSE) -> 0 | I14: 0 | R14: =+I14+L14+N14-P14 -> 0 | AC14: =+R14+W14+Y14-AA14 -> 0
A15: 253 | E15: =CONCATENATE(B15,"-",C15,"-",D15) -> -- | F15: =VLOOKUP(E15,'LISTA ITEMS'!$E$2:$G$875,2,FALSE) -> 0 | G15: =VLOOKUP(E15,'LISTA ITEMS'!$E$2:$G$875,3,FALSE) -> 0 | I15: 0 | R15: =+I15+L15+N15-P15 -> 0 | AC15: =+R15+W15+Y15-AA15 -> 0
... A33: 271 | E33: =CONCATENATE(B33,"-",C33,"-",D33) -> -- | F33: =VLOOKUP(E33,'LISTA ITEMS'!$E$2:$G$875,2,FALSE) -> 0 | G33: =VLOOKUP(E33,'LISTA ITEMS'!$E$2:$G$875,3,FALSE) -> 0 | I33: 0 | R33: =+I33+L33+N33-P33 -> 0 | AC33: =+R33+W33+Y33-AA33 -> 0
A34: 272 | E34: =CONCATENATE(B34,"-",C34,"-",D34) -> -- | F34: =VLOOKUP(E34,'LISTA ITEMS'!$E$2:$G$875,2,FALSE) -> 0 | G34: =VLOOKUP(E34,'LISTA ITEMS'!$E$2:$G$875,3,FALSE) -> 0 | I34: 0 | R34: =+I34+L34+N34-P34 -> 0 | AC34: =+R34+W34+Y34-AA34 -> 0 | AI34: OK
A35: 273 | E35: =CONCATENATE(B35,"-",C35,"-",D35) -> -- | F35: =VLOOKUP(E35,'LISTA ITEMS'!$E$2:$G$875,2,FALSE) -> 0 | G35: =VLOOKUP(E35,'LISTA ITEMS'!$E$2:$G$875,3,FALSE) -> 0 | I35: 0 | R35: =+I35+L35+N35-P35 -> 0 | AC35: =+R35+W35+Y35-AA35 -> 0 | AI35: OK
A36: 274 | E36: =CONCATENATE(B36,"-",C36,"-",D36) -> -- | F36: =VLOOKUP(E36,'LISTA ITEMS'!$E$2:$G$875,2,FALSE) -> 0 | G36: =VLOOKUP(E36,'LISTA ITEMS'!$E$2:$G$875,3,FALSE) -> 0 | I36: 0 | R36: =+I36+L36+N36-P36 -> 0 | AC36: =+R36+W36+Y36-AA36 -> 0 | AI36: OK
A37: 275 | E37: =CONCATENATE(B37,"-",C37,"-",D37) -> -- | F37: =VLOOKUP(E37,'LISTA ITEMS'!$E$2:$G$875,2,FALSE) -> 0 | G37: =VLOOKUP(E37,'LISTA ITEMS'!$E$2:$G$875,3,FALSE) -> 0 | I37: 0 | R37: =+I37+L37+N37-P37 -> 0 | AC37: =+R37+W37+Y37-AA37 -> 0 | AI37: OK
A38: 276 | E38: =CONCATENATE(B38,"-",C38,"-",D38) -> -- | F38: =VLOOKUP(E38,'LISTA ITEMS'!$E$2:$G$875,2,FALSE) -> 0 | G38: =VLOOKUP(E38,'LISTA ITEMS'!$E$2:$G$875,3,FALSE) -> 0 | I38: 0 | R38: =+I38+L38+N38-P38 -> 0 | AC38: =+R38+W38+Y38-AA38 -> 0 | AI38: OK
A39: 277 | E39: =CONCATENATE(B39,"-",C39,"-",D39) -> -- | F39: =VLOOKUP(E39,'LISTA ITEMS'!$E$2:$G$875,2,FALSE) -> 0 | G39: =VLOOKUP(E39,'LISTA ITEMS'!$E$2:$G$875,3,FALSE) -> 0 | I39: 0 | R39: =+I39+L39+N39-P39 -> 0 | AC39: =+R39+W39+Y39-AA39 -> 0 | AI39: OK
A40: 278 | E40: =CONCATENATE(B40,"-",C40,"-",D40) -> -- | F40: =VLOOKUP(E40,'LISTA ITEMS'!$E$2:$G$875,2,FALSE) -> 0 | G40: =VLOOKUP(E40,'LISTA ITEMS'!$E$2:$G$875,3,FALSE) -> 0 | I40: 0 | R40: =+I40+L40+N40-P40 -> 0 | AC40: =+R40+W40+Y40-AA40 -> 0 | AI40: OK
A41: 279 | E41: =CONCATENATE(B41,"-",C41,"-",D41) -> -- | F41: =VLOOKUP(E41,'LISTA ITEMS'!$E$2:$G$875,2,FALSE) -> 0 | G41: =VLOOKUP(E41,'LISTA ITEMS'!$E$2:$G$875,3,FALSE) -> 0 | I41: 0 | R41: =+I41+L41+N41-P41 -> 0 | AC41: =+R41+W41+Y41-AA41 -> 0 | AI41: OK
A42: 280 | E42: =CONCATENATE(B42,"-",C42,"-",D42) -> -- | F42: =VLOOKUP(E42,'LISTA ITEMS'!$E$2:$G$875,2,FALSE) -> 0 | G42: =VLOOKUP(E42,'LISTA ITEMS'!$E$2:$G$875,3,FALSE) -> 0 | I42: 0 | R42: =+I42+L42+N42-P42 -> 0 | AC42: =+R42+W42+Y42-AA42 -> 0 | AI42: OK
A43: 281 | E43: =CONCATENATE(B43,"-",C43,"-",D43) -> -- | F43: =VLOOKUP(E43,'LISTA ITEMS'!$E$2:$G$875,2,FALSE) -> 0 | G43: =VLOOKUP(E43,'LISTA ITEMS'!$E$2:$G$875,3,FALSE) -> 0 | I43: 0 | R43: =+I43+L43+N43-P43 -> 0 | AC43: =+R43+W43+Y43-AA43 -> 0 | AI43: OK
A44: 282 | E44: =CONCATENATE(B44,"-",C44,"-",D44) -> -- | F44: =VLOOKUP(E44,'LISTA ITEMS'!$E$2:$G$875,2,FALSE) -> 0 | G44: =VLOOKUP(E44,'LISTA ITEMS'!$E$2:$G$875,3,FALSE) -> 0 | I44: 0 | R44: =+I44+L44+N44-P44 -> 0 | AC44: =+R44+W44+Y44-AA44 -> 0 | AI44: OK
A45: 283 | E45: =CONCATENATE(B45,"-",C45,"-",D45) -> -- | F45: =VLOOKUP(E45,'LISTA ITEMS'!$E$2:$G$875,2,FALSE) -> 0 | G45: =VLOOKUP(E45,'LISTA ITEMS'!$E$2:$G$875,3,FALSE) -> 0 | I45: 0 | R45: =+I45+L45+N45-P45 -> 0 | AC45: =+R45+W45+Y45-AA45 -> 0 | AI45: OK
... A47: 285 | E47: =CONCATENATE(B47,"-",C47,"-",D47) -> -- | F47: =VLOOKUP(E47,'LISTA ITEMS'!$E$2:$G$875,2,FALSE) -> 0 | G47: =VLOOKUP(E47,'LISTA ITEMS'!$E$2:$G$875,3,FALSE) -> 0 | I47: 0 | R47: =+I47+L47+N47-P47 -> 0 | AC47: =+R47+W47+Y47-AA47 -> 0 | AI47: OK
A48: 286 | E48: =CONCATENATE(B48,"-",C48,"-",D48) -> -- | F48: =VLOOKUP(E48,'LISTA ITEMS'!$E$2:$G$875,2,FALSE) -> 0 | G48: =VLOOKUP(E48,'LISTA ITEMS'!$E$2:$G$875,3,FALSE) -> 0 | I48: 0 | R48: =+I48+L48+N48-P48 -> 0 | AC48: =+R48+W48+Y48-AA48 -> 0
A49: 287 | E49: =CONCATENATE(B49,"-",C49,"-",D49) -> -- | F49: =VLOOKUP(E49,'LISTA ITEMS'!$E$2:$G$875,2,FALSE) -> 0 | G49: =VLOOKUP(E49,'LISTA ITEMS'!$E$2:$G$875,3,FALSE) -> 0 | I49: 0 | R49: =+I49+L49+N49-P49 -> 0 | AC49: =+R49+W49+Y49-AA49 -> 0
A50: 288 | E50: =CONCATENATE(B50,"-",C50,"-",D50) -> -- | F50: =VLOOKUP(E50,'LISTA ITEMS'!$E$2:$G$875,2,FALSE) -> 0 | G50: =VLOOKUP(E50,'LISTA ITEMS'!$E$2:$G$875,3,FALSE) -> 0 | I50: 0 | R50: =+I50+L50+N50-P50 -> 0 | AC50: =+R50+W50+Y50-AA50 -> 0
A51: 289 | E51: =CONCATENATE(B51,"-",C51,"-",D51) -> -- | F51: =VLOOKUP(E51,'LISTA ITEMS'!$E$2:$G$875,2,FALSE) -> 0 | G51: =VLOOKUP(E51,'LISTA ITEMS'!$E$2:$G$875,3,FALSE) -> 0 | I51: 0 | R51: =+I51+L51+N51-P51 -> 0 | AC51: =+R51+W51+Y51-AA51 -> 0
A52: 290 | E52: =CONCATENATE(B52,"-",C52,"-",D52) -> -- | F52: =VLOOKUP(E52,'LISTA ITEMS'!$E$2:$G$875,2,FALSE) -> 0 | G52: =VLOOKUP(E52,'LISTA ITEMS'!$E$2:$G$875,3,FALSE) -> 0 | I52: 0 | R52: =+I52+L52+N52-P52 -> 0 | AC52: =+R52+W52+Y52-AA52 -> 0
A53: 291 | E53: =CONCATENATE(B53,"-",C53,"-",D53) -> -- | F53: =VLOOKUP(E53,'LISTA ITEMS'!$E$2:$G$875,2,FALSE) -> 0 | G53: =VLOOKUP(E53,'LISTA ITEMS'!$E$2:$G$875,3,FALSE) -> 0 | I53: 0 | R53: =+I53+L53+N53-P53 -> 0 | AC53: =+R53+W53+Y53-AA53 -> 0
A54: 292 | E54: =CONCATENATE(B54,"-",C54,"-",D54) -> -- | F54: =VLOOKUP(E54,'LISTA ITEMS'!$E$2:$G$875,2,FALSE) -> 0 | G54: =VLOOKUP(E54,'LISTA ITEMS'!$E$2:$G$875,3,FALSE) -> 0 | I54: 0 | R54: =+I54+L54+N54-P54 -> 0 | AC54: =+R54+W54+Y54-AA54 -> 0
A55: 293 | E55: =CONCATENATE(B55,"-",C55,"-",D55) -> -- | F55: =VLOOKUP(E55,'LISTA ITEMS'!$E$2:$G$875,2,FALSE) -> 0 | G55: =VLOOKUP(E55,'LISTA ITEMS'!$E$2:$G$875,3,FALSE) -> 0 | I55: 0 | R55: =+I55+L55+N55-P55 -> 0 | AC55: =+R55+W55+Y55-AA55 -> 0
A56: 294 | E56: =CONCATENATE(B56,"-",C56,"-",D56) -> -- | F56: =VLOOKUP(E56,'LISTA ITEMS'!$E$2:$G$875,2,FALSE) -> 0 | G56: =VLOOKUP(E56,'LISTA ITEMS'!$E$2:$G$875,3,FALSE) -> 0 | I56: 0 | R56: =+I56+L56+N56-P56 -> 0 | AC56: =+R56+W56+Y56-AA56 -> 0
A57: 295 | E57: =CONCATENATE(B57,"-",C57,"-",D57) -> -- | F57: =VLOOKUP(E57,'LISTA ITEMS'!$E$2:$G$875,2,FALSE) -> 0 | G57: =VLOOKUP(E57,'LISTA ITEMS'!$E$2:$G$875,3,FALSE) -> 0 | I57: 0 | R57: =+I57+L57+N57-P57 -> 0 | AC57: =+R57+W57+Y57-AA57 -> 0
A58: 296 | E58: =CONCATENATE(B58,"-",C58,"-",D58) -> -- | F58: =VLOOKUP(E58,'LISTA ITEMS'!$E$2:$G$875,2,FALSE) -> 0 | G58: =VLOOKUP(E58,'LISTA ITEMS'!$E$2:$G$875,3,FALSE) -> 0 | I58: 0 | R58: =+I58+L58+N58-P58 -> 0 | AC58: =+R58+W58+Y58-AA58 -> 0
...

Sheet INV CRISTOBAL 23-3
A1: FMT-01-INV | D1: RELACION TOMA DE INVENTARIOS DIARIOS | H1: TOMA INVENTARIO | K1: UBICACIÓN FISICA
A2: LINEA | B2: GRUPO | C2: ELEMENTO | D2: ITEM | E2: CONCATENADO | F2: DESCRIPCION | G2: UND MEDIDA | H2: FECHA | I2: CANTIDAD | J2: NOTA | K2: ZONA | L2: ESTAN | M2: NIVEL
A3: 97 | B3: 7 | C3: 54 | D3: 295 | E3: =CONCATENATE(B3,"-",C3,"-",D3) -> 7-54-295 | F3: =VLOOKUP(E3,'LISTA ITEMS'!$E$2:$G$875,2,FALSE) -> BATERIA LFP LITHIUM DL5.OC (DYNESS) | G3: =VLOOKUP(E3,'LISTA ITEMS'!$E$2:$G$875,3,FALSE) -> UND | H3: 46104 | I3: 5 | K3: 6 | L3: N/A | M3: SUELO
A4: 243 | B4: 7 | C4: 54 | D4: 423 | E4: 7-54-423 | F4: BATERIA LFP LITHIUM DL5.OC RACK (DYNESS) | G4: UND | H4: 46104 | I4: 8 | K4: AREA RECIBO | L4: PALLET | M4: SUELO
A5: 115 | B5: 7 | C5: 54 | D5: 323 | E5: =CONCATENATE(B5,"-",C5,"-",D5) -> 7-54-323 | F5: =VLOOKUP(E5,'LISTA ITEMS'!$E$2:$G$875,2,FALSE) -> BATERIA LPF LITHIUM B3 48V 3.6kWh (DYNESS) | G5: =VLOOKUP(E5,'LISTA ITEMS'!$E$2:$G$875,3,FALSE) -> UND | H5: 46104 | I5: 1 | K5: AREA RECIBO | L5: PALLET | M5: SUELO
A6: 226 | B6: 7 | C6: 54 | D6: 404 | E6: =CONCATENATE(B6,"-",C6,"-",D6) -> 7-54-404 | F6: =VLOOKUP(E6,'LISTA ITEMS'!$E$2:$G$875,2,FALSE) -> BATERIA RECARGABLE LITHIUM DL10 POWERBOX G2 (DYNESS) | G6: =VLOOKUP(E6,'LISTA ITEMS'!$E$2:$G$875,3,FALSE) -> UND | H6: 46104 | I6: 1 | K6: AREA RECIBO | L6: PALLET | M6: SUELO
A7: 205 | B7: 16 | C7: 45 | D7: 383 | E7: =CONCATENATE(B7,"-",C7,"-",D7) -> 16-45-383 | F7: =VLOOKUP(E7,'LISTA ITEMS'!$E$2:$G$875,2,FALSE) -> CAJA BLANCA P/BATERIA (DYNNES) | G7: =VLOOKUP(E7,'LISTA ITEMS'!$E$2:$G$875,3,FALSE) -> UND | H7: 46104 | I7: 3 | K7: 6 | L7: PALLET | M7: SUELO
A8: 180 | B8: 7 | C8: 35 | D8: 286 | E8: =CONCATENATE(B8,"-",C8,"-",D8) -> 7-35-286 | F8: =VLOOKUP(E8,'LISTA ITEMS'!$E$2:$G$875,2,FALSE) -> INVERSOR SPH 6000TL BL-UP 6KW (GROWATT) | G8: =VLOOKUP(E8,'LISTA ITEMS'!$E$2:$G$875,3,FALSE) -> UND | H8: 46104 | I8: 8 | K8: 6 | L8: N/A | M8: SUELO
A9: 55 | B9: 7 | C9: 38 | D9: 237 | E9: =CONCATENATE(B9,"-",C9,"-",D9) -> 7-38-237 | F9: =VLOOKUP(E9,'LISTA ITEMS'!$E$2:$G$875,2,FALSE) -> PLACA SOLAR CS6.1-60TB-505 505W / 43.4V | G9: =VLOOKUP(E9,'LISTA ITEMS'!$E$2:$G$875,3,FALSE) -> UND | H9: 46104 | I9: 2 | J9: NEGRA | K9: 5 | L9: PARED | M9: 1
A10: 53 | B10: 7 | C10: 38 | D10: 235 | E10: =CONCATENATE(B10,"-",C10,"-",D10) -> 7-38-235 | F10: =VLOOKUP(E10,'LISTA ITEMS'!$E$2:$G$875,2,FALSE) -> PLACA SOLAR CS6L-450MS 450W / 34.4V | G10: =VLOOKUP(E10,'LISTA ITEMS'!$E$2:$G$875,3,FALSE) -> UND | H10: 46104 | I10: 1 | J10: NEGRA | K10: 5 | L10: PARED | M10: 5
A11: 60 | B11: 7 | C11: 38 | D11: 242 | E11: =CONCATENATE(B11,"-",C11,"-",D11) -> 7-38-242 | F11: =VLOOKUP(E11,'LISTA ITEMS'!$E$2:$G$875,2,FALSE) -> PLACA SOLAR CS6W-585T 585W / 52.4V | G11: =VLOOKUP(E11,'LISTA ITEMS'!$E$2:$G$875,3,FALSE) -> UND | H11: 46104 | I11: 3 | J11: GRIS | K11: 5 | L11: PARED | M11: 5
A12: 52 | B12: 7 | C12: 38 | D12: 234 | E12: =CONCATENATE(B12,"-",C12,"-",D12) -> 7-38-234 | F12: =VLOOKUP(E12,'LISTA ITEMS'!$E$2:$G$875,2,FALSE) -> PLACA SOLAR CSP-6P-345W / 38.3C | G12: =VLOOKUP(E12,'LISTA ITEMS'!$E$2:$G$875,3,FALSE) -> UND | H12: 46104 | I12: 1 | J12: GRIS | K12: 5 | L12: PARED | M12: 4
A13: 51 | B13: 7 | C13: 38 | D13: 233 | E13: =CONCATENATE(B13,"-",C13,"-",D13) -> 7-38-233 | F13: =VLOOKUP(E13,'LISTA ITEMS'!$E$2:$G$875,2,FALSE) -> PLACA SOLAR EX-275P-60 275W / 31.50V | G13: =VLOOKUP(E13,'LISTA ITEMS'!$E$2:$G$875,3,FALSE) -> UND | H13: 46104 | I13: 1 | J13: GRIS | K13: 5 | L13: PARED | M13: 3
A14: 65 | B14: 7 | C14: 38 | D14: 247 | E14: =CONCATENATE(B14,"-",C14,"-",D14) -> 7-38-247 | F14: =VLOOKUP(E14,'LISTA ITEMS'!$E$2:$G$875,2,FALSE) -> PLACA SOLAR JAM60D42-535LB 535W / 44.13V | G14: =VLOOKUP(E14,'LISTA ITEMS'!$E$2:$G$875,3,FALSE) -> UND | H14: 46104 | I14: =3*36+11 -> 119 | J14: NEGRA | K14: 6 | L14: N/A | M14: SUELO
A15: 54 | B15: 7 | C15: 38 | D15: 236 | E15: =CONCATENATE(B15,"-",C15,"-",D15) -> 7-38-236 | F15: =VLOOKUP(E15,'LISTA ITEMS'!$E$2:$G$875,2,FALSE) -> PLACA SOLAR JAM66S30-505MR 505W / 45.72V | G15: =VLOOKUP(E15,'LISTA ITEMS'!$E$2:$G$875,3,FALSE) -> UND | H15: 46104 | I15: 1 | J15: GRIS | K15: 5 | L15: PARED | M15: 2
A16: 58 | B16: 7 | C16: 38 | D16: 240 | E16: =CONCATENATE(B16,"-",C16,"-",D16) -> 7-38-240 | F16: =VLOOKUP(E16,'LISTA ITEMS'!$E$2:$G$875,2,FALSE) -> PLACA SOLAR JAM72D30-545MB 545W / 49.75V | G16: =VLOOKUP(E16,'LISTA ITEMS'!$E$2:$G$875,3,FALSE) -> UND | H16: 46104 | I16: 1 | J16: GRIS | K16: 5 | L16: PARED | M16: 8
A17: 63 | B17: 7 | C17: 38 | D17: 245 | E17: =CONCATENATE(B17,"-",C17,"-",D17) -> 7-38-245 | F17: =VLOOKUP(E17,'LISTA ITEMS'!$E$2:$G$875,2,FALSE) -> PLACA SOLAR JAM72D40-590MB 590W / 52.37V | G17: =VLOOKUP(E17,'LISTA ITEMS'!$E$2:$G$875,3,FALSE) -> UND | H17: 46104 | I17: 2 | J17: GRIS | K17: 5 | L17: PARED | M17: 3
A18: 67 | B18: 7 | C18: 38 | D18: 249 | E18: =CONCATENATE(B18,"-",C18,"-",D18) -> 7-38-249 | F18: =VLOOKUP(E18,'LISTA ITEMS'!$E$2:$G$875,2,FALSE) -> PLACA SOLAR JAM72S30-570LR 570W / 50.68V | G18: =VLOOKUP(E18,'LISTA ITEMS'!$E$2:$G$875,3,FALSE) -> UND | H18: 46104 | I18: 9 | J18: GRIS | K18: 4 | L18: PALLET | M18: SUELO
A19: 57 | B19: 7 | C19: 38 | D19: 239 | E19: =CONCATENATE(B19,"-",C19,"-",D19) -> 7-38-239 | F19: =VLOOKUP(E19,'LISTA ITEMS'!$E$2:$G$875,2,FALSE) -> PLACA SOLAR JAMS0D42-520LB 520W / 43.53V | G19: =VLOOKUP(E19,'LISTA ITEMS'!$E$2:$G$875,3,FALSE) -> UND | H19: 46104 | I19: 1 | J19: GRIS | K19: 5 | L19: PARED | M19: 8
A20: 59 | B20: 7 | C20: 38 | D20: 241 | E20: =CONCATENATE(B20,"-",C20,"-",D20) -> 7-38-241 | F20: =VLOOKUP(E20,'LISTA ITEMS'!$E$2:$G$875,2,FALSE) -> PLACA SOLAR PS555M6H-24TH 555W / 41.64V | G20: =VLOOKUP(E20,'LISTA ITEMS'!$E$2:$G$875,3,FALSE) -> UND | H20: 46104 | I20: 2 | J20: GRIS | K20: 5 | L20: PARED | M20: 7
A21: 242 | B21: 7 | C21: 38 | D21: 422 | E21: =CONCATENATE(B21,"-",C21,"-",D21) -> 7-38-422 | F21: =VLOOKUP(E21,'LISTA ITEMS'!$E$2:$G$875,2,FALSE) -> PLACA SOLAR PS595M8GFH-24/TNH 595W (PHONO) | G21: =VLOOKUP(E21,'LISTA ITEMS'!$E$2:$G$875,3,FALSE) -> UND | H21: 46104 | I21: 15 | J21: CLIENTE AGRISUR GRIS | K21: 5 | L21: PALLET | M21: SUELO
A22: 62 | B22: 7 | C22: 38 | D22: 244 | E22: =CONCATENATE(B22,"-",C22,"-",D22) -> 7-38-244 | F22: =VLOOKUP(E22,'LISTA ITEMS'!$E$2:$G$875,2,FALSE) -> PLACA SOLAR SK9612MHVC-550 550W / 42.16V | G22: =VLOOKUP(E22,'LISTA ITEMS'!$E$2:$G$875,3,FALSE) -> UND | H22: 46104 | I22: 1 | J22: GRIS | K22: 5 | L22: PARED | M22: 2
A23: 56 | B23: 7 | C23: 38 | D23: 238 | E23: =CONCATENATE(B23,"-",C23,"-",D23) -> 7-38-238 | F23: =VLOOKUP(E23,'LISTA ITEMS'!$E$2:$G$875,2,FALSE) -> PLACA SOLAR SPR-P3-375-BLK-E4-AC 375W / 35.5V | G23: =VLOOKUP(E23,'LISTA ITEMS'!$E$2:$G$875,3,FALSE) -> UND | H23: 46104 | I23: 1 | J23: NEGRA | K23: 5 | L23: PARED | M23: 7
A24: 64 | B24: 7 | C24: 38 | D24: 246 | E24: =CONCATENATE(B24,"-",C24,"-",D24) -> 7-38-246 | F24: =VLOOKUP(E24,'LISTA ITEMS'!$E$2:$G$875,2,FALSE) -> PLACA SOLAR TSM-505DE18M.08(II) 505W / 43.0V | G24: =VLOOKUP(E24,'LISTA ITEMS'!$E$2:$G$875,3,FALSE) -> UND | H24: 46104 | I24: 2 | J24: NEGRA | K24: 5 | L24: PARED | M24: 4
A25: 61 | B25: 7 | C25: 38 | D25: 243 | E25: =CONCATENATE(B25,"-",C25,"-",D25) -> 7-38-243 | F25: =VLOOKUP(E25,'LISTA ITEMS'!$E$2:$G$875,2,FALSE) -> PLACA SOLAR YL550D-49e 1500V 1/2 550W / 42.0V | G25: =VLOOKUP(E25,'LISTA ITEMS'!$E$2:$G$875,3,FALSE) -> UND | H25: 46104 | I25: 1 | J25: GRIS | K25: 5 | L25: PARED | M25: 1
L54: 2
