Workbook

Sheet LISTA ITEMS
A1: GRUPO | B1: ELEMENTO | C1: ITEM | D1: CONCATENADO | E1: DESCRIPCION | F1: UND MEDIDA | G1: PROVEEDOR
A2: 7 | B2: 20 | C2: 178 | D2: 7-20-178 | E2: ESTUFA CALEFACCION 9 KW | F2: UND | G2: 0
A3: 7 | B3: 20 | C3: 179 | D3: 7-20-179 | E3: ESTUFA CALEFACCION 12 KW | F3: UND | G3: 0
A4: 13 | B4: 21 | C4: 180 | D4: 13-21-180 | E4: TACO P/BRIDA BLANCO | F4: UND | G4: RECA
A5: 13 | B5: 21 | C5: 181 | D5: 13-21-181 | E5: TACO P/BRIDA NEGRO | F5: UND | G5: RECA
A6: 13 | B6: 22 | C6: 182 | D6: 13-22-182 | E6: BRIDA P/INTERIOR BLANCA | F6: UND | G6: RECA
A7: 13 | B7: 22 | C7: 183 | D7: 13-22-183 | E7: BRIDA P/INTERIOR NEGRA | F7: UND | G7: RECA
A8: 13 | B8: 22 | C8: 184 | D8: 13-22-184 | E8: BRIDA P/EXTERIOR NEGRA | F8: UND | G8: RECA
A9: 13 | B9: 23 | C9: 185 | D9: 13-23-185 | E9: CINTA BLANCA AISLANTE PVC 50MM | F9: UND | G9: RECA
A10: 13 | B10: 23 | C10: 186 | D10: 13-23-186 | E10: CINTA NEGRA AISLANTE PVC 50MM | F10: UND | G10: RECA
A11: 13 | B11: 23 | C11: 187 | D11: 13-23-187 | E11: CINTA VERDE AMARILLA AISLANTE PVC 19MM | F11: UND | G11: RECA
A12: 13 | B12: 23 | C12: 188 | D12: 13-23-188 | E12: CINTA ROJA AISLANTE PVC 19MM | F12: UND | G12: RECA
A13: 13 | B13: 23 | C13: 189 | D13: 13-23-189 | E13: CINTA AZUL AISLANTE PVC 19MM | F13: UND | G13: RECA
A14: 13 | B14: 23 | C14: 190 | D14: 13-23-190 | E14: CINTA BLANCA AISLANTE PVC 19MM | F14: UND | G14: RECA
A15: 13 | B15: 23 | C15: 191 | D15: 13-23-191 | E15: CINTA NEGRA AISLANTE PVC 19MM | F15: UND | G15: RECA
... A103: 3 | B103: 31 | C103: 278 | D103: 3-31-278 | E103: CABLE Nª 10 P/PLACA SOLAR ROJO | F103: MT | G103: COTO
A104: 16 | B104: 46 | C104: 279 | D104: 16-46-279 | E104: MANGUERA CORRUGADA NEGRA | F104: MT | G104: 0
A105: 16 | B105: 47 | C105: 280 | D105: 16-47-280 | E105: DIFERENCIAL EPR2A063030 2P-63A-30mA (MAXGE) | F105: UND | G105: BELTRAN Y CRIADO
A106: 16 | B106: 48 | C106: 281 | D106: 16-48-281 | E106: PORTA FUSIBLE SGF-32-DC (MAXGE) | F106: UND | G106: BELTRAN Y CRIADO
A107: 16 | B107: 49 | C107: 282 | D107: 16-49-282 | E107: CONTACTOR MODULAR RV32 (REVALCO) | F107: UND | G107: INVERSOLAR
A108: 16 | B108: 50 | C108: 283 | D108: 16-50-283 | E108: FUSIBLE 32A-1000VDC (SASSIN) | F108: UND | G108: BELTRAN Y CRIADO
A109: 16 | B109: 51 | C109: 284 | D109: 16-51-284 | E109: LIMITADOR MONOFASICO 3SUR1 15/30kA-275V (SASSIN) | F109: UND | G109: BELTRAN Y CRIADO
A110: 16 | B110: 52 | C110: 285 | D110: 16-52-285 | E110: TERMICO EPBE63M1NC63 1P+N C63 (MAXGE) | F110: UND | G110: BELTRAN Y CRIADO
D111: -- | E111: 0 | F111: 0 | G111: 0
D112: -- | E112: 0 | F112: 0 | G112: 0
D113: -- | E113: 0 | F113: 0 | G113: 0
D114: -- | E114: 0 | F114: 0 | G114: 0
D115: -- | E115: 0 | F115: 0 | G115: 0
D116: -- | E116: 0 | F116: 0 | G116: 0
D117: -- | E117: 0 | F117: 0 | G117: 0
D118: -- | E118: 0 | F118: 0 | G118: 0
D119: -- | E119: 0 | F119: 0 | G119: 0
D120: -- | E120: 0 | F120: 0 | G120: 0
D121: -- | E121: 0 | F121: 0 | G121: 0
D122: -- | E122: 0 | F122: 0 | G122: 0
... D876: -- | E876: 0 | F876: 0 | G876: 0

Sheet FMT BASE TECNICOS
A1: FORMATO TOMA DE MATERIALES (TECNICOS) | H1: FMT-02-ALM
A2: LINEA | B2: CLIENTE | C2: CODIGO | F2: UND MEDIDA | G2: CANTIDAD | H2: NOMBRE
A3: 1
A4: =+A3+1 -> 2
A5: =+A4+1 -> 3
A6: =+A5+1 -> 4
A7: =+A6+1 -> 5
A8: =+A7+1 -> 6
A9: =+A8+1 -> 7
A10: =+A9+1 -> 8
A11: =+A10+1 -> 9
A12: =+A11+1 -> 10
A13: =+A12+1 -> 11
A14: =+A13+1 -> 12
A15: =+A14+1 -> 13
... A21: =+A20+1 -> 19

Sheet FMT BASE
A1: FMT-03-ALM | C1: FORMATO ALISTAMIENTO DE MATERIALES (ALMACENISTA) | F1: CONSEC. #
A2: CLIENTE | F2: PARTE TRAB. #
A3: CIUDAD | E3: ALISTADO POR: | F3: FECHA REQUER.
A4: LINEA | B4: CODIGO | E4: DESCRIPCION | F4: UND MED. | G4: CANT. | H4: VERIFICA TECNICO
A5: 1
A6: 2
A7: 3
A8: 4
A9: 5
A10: 6
A11: 7
A12: 8
A13: 9
A14: 10
A15: 11
A16: 12
... A36: 32

Sheet Hector 05feb
A1: FMT-03-ALM | C1: FORMATO ALISTAMIENTO DE MATERIALES (ALMACENISTA) | F1: CONSEC. # | H1: 1 | J1: REGISTRO | K1: OK
A2: CLIENTE | C2: JESUS MORALES BUSTOS | F2: PARTE TRAB. # | H2: 2 | J2: DEVOLUCION | K2: OK
A3: CIUDAD | C3: JAEN | E3: ALISTADO POR: FABIO GUTIERREZ | F3: FECHA 02feb2026 REQUER.
A4: LINEA | B4: CODIGO | E4: DESCRIPCION | F4: UND MED. | G4: CANT. | H4: VERIFICA TECNICO | I4: FECHA | J4: DEVOLUC. | K4: CANT. REAL CONSUMIDA
A5: 1 | B5: 13 | C5: 22 | D5: 184 | E5: BRIDA P/EXTERIOR NEGRA | F5: UND | G5: 100 | H5: si | I5: 46058 | J5: 50 | K5: =+G5-J5 -> 50
A6: 2 | B6: 6 | C6: 23 | D6: 192 | E6: CINTA ACERO PERFORADA PARA MONTAJE | F6: UND | G6: 2 | H6: si | I6: 46058 | J6: 2 | K6: =+G6-J6 -> 0
A7: 3 | B7: 14 | C7: 24 | D7: 193 | E7: DISCO CORTE ACERO/INOX A1 2EN1 | F7: UND | G7: 1 | H7: si | I7: 46058 | J7: 1 | K7: =+G7-J7 -> 0
A8: 4 | B8: 3 | C8: 31 | D8: 209 | E8: CABLE Nª 6 C/ALTERNA MARRON | F8: MT | G8: 100 | H8: si | I8: 46058 | J8: 100 | K8: =+G8-J8 -> 0
A9: 5 | B9: 3 | C9: 31 | D9: 210 | E9: CABLE Nª 6 C/ALTERNA GRIS | F9: MT | G9: 100 | H9: si | I9: 46058 | J9: 100 | K9: =+G9-J9 -> 0
A10: 6 | B10: 3 | C10: 31 | D10: 212 | E10: CABLE Nª 6 C/ALTERNA AZUL | F10: MT | G10: 100 | H10: si | I10: 46058 | J10: 100 | K10: =+G10-J10 -> 0
A11: 7 | B11: 3 | C11: 31 | D11: 213 | E11: CABLE Nª 6 C/ALTERNA NEGRO | F11: MT | G11: 100 | H11: si | I11: 46058 | J11: 100 | K11: =+G11-J11 -> 0
A12: 8 | B12: 9 | C12: 32 | D12: 223 | E12: CURVA PVC M-25 GRIS TIPO A | F12: UND | G12: 30 | H12: si | I12: 46058 | J12: 22 | K12: =+G12-J12 -> 8
A13: 9 | B13: 4 | C13: 15 | D13: 267 | E13: BARRA PERFORADA PARA REFUERZO 20X10X2MT GALV. | F13: UND | G13: 30 | H13: si | K13: =+G13-J13 -> 30
A14: 10 | B14: 10 | C14: 42 | D14: 268 | E14: PATA ALUMINIO PARA ESTRUCTURA PLACA SOLAR | F14: UND | G14: 20 | H14: si | I14: 46058 | J14: 10 | K14: =+G14-J14 -> 10
A15: 11 | B15: 10 | C15: 15 | D15: 269 | E15: BARRA ALUMINIO PARA ESTRUCTURA | F15: UND | G15: 19 | H15: si | K15: =+G15-J15 -> 19
A16: 12 | B16: 13 | C16: 25 | D16: 255 | E16: ANCLAJE PLASTICO MULTIUSO C/COLLARIN 10X61MM | F16: UND | G16: 50 | H16: si | I16: 46058 | J16: 50 | K16: =+G16-J16 -> 0
A17: 13 | B17: 10 | C17: 43 | D17: 270 | E17: EMPALME ALUMINIO P/BARRA | F17: UND | G17: 15 | H17: si | I17: 46058 | J17: 15 | K17: =+G17-J17 -> 0
A18: 14 | B18: 17 | C18: 44 | D18: 271 | E18: SELLANTE QUIMICO BLANCO | F18: UND | G18: 2 | H18: si | I18: 46058 | J18: 2 | K18: =+G18-J18 -> 0
A19: 15 | B19: 17 | C19: 44 | D19: 272 | E19: SELLANTE QUIMICO GRIS | F19: UND | G19: 1 | H19: si | I19: 46058 | J19: 0.5 | K19: =+G19-J19 -> 0.5
A20: 16 | B20: 7 | C20: 35 | D20: 274 | E20: INVERSOR HIBRIDO MONOFASICO SPE 10000ES 10KW BATER. BAJO VOLTAJE Y BACKUP INCORP. (GROWATT) | F20: UND | G20: 1 | H20: si | J20: HAQ1F4P4JV | K20: 1
A21: 17 | B21: 16 | C21: 45 | D21: 275 | E21: CAJA DISTRIBUCION INTERIOR 18 ELEM. (SOLERA) | F21: UND | G21: 1 | H21: si | K21: =+G21-J21 -> 1
A22: 18 | B22: 16 | C22: 45 | D22: 276 | E22: CAJA ESTANCA (COCHERA) EXTERIOR 18PT (IDE) | F22: UND | G22: 1 | H22: si | K22: =+G22-J22 -> 1
A23: 19 | B23: 3 | C23: 31 | D23: 277 | E23: CABLE Nª 10 P/PLACA SOLAR NEGRO | F23: MT | G23: 30 | H23: si | K23: =+G23-J23 -> 30
A24: 20 | B24: 3 | C24: 31 | D24: 278 | E24: CABLE Nª 10 P/PLACA SOLAR ROJO | F24: MT | G24: 30 | H24: si | K24: =+G24-J24 -> 30
A25: 21 | B25: 16 | C25: 46 | D25: 279 | E25: MANGUERA CORRUGADA NEGRA | F25: MT | G25: 2 | H25: si | I25: 46058 | J25: 1 | K25: =+G25-J25 -> 1
A26: 22 | B26: 3 | C26: 31 | D26: 222 | E26: CABLE Nª 10 C/ALTERNA NEGRO | F26: MT | G26: 100 | H26: si | I26: 46058 | J26: 88 | K26: =+G26-J26 -> 12
A27: 23 | B27: 3 | C27: 31 | D27: 221 | E27: CABLE Nª 10 C/ALTERNA AZUL | F27: MT | G27: 100 | H27: si | I27: 46058 | J27: 88 | K27: =+G27-J27 -> 12
A28: 24 | B28: 3 | C28: 31 | D28: 220 | E28: CABLE Nª 10 C/ALTERNA GRIS | F28: MT | G28: 100 | H28: si | I28: 46058 | J28: 88 | K28: =+G28-J28 -> 12
A29: 25 | B29: 3 | C29: 31 | D29: 219 | E29: CABLE Nª 10 C/ALTERNA MARRON | F29: MT | G29: 100 | H29: si | I29: 46058 | J29: 88 | K29: =+G29-J29 -> 12
A30: 26 | B30: 3 | C30: 31 | D30: 218 | E30: CABLE Nª 10 C/ALTERNA VERDE/AMARILLO | F30: MT | G30: 60 | H30: si | I30: 46058 | J30: 88 | K30: =+G30-J30 -> -28
A31: 27 | B31: 16 | C31: 47 | D31: 280 | E31: DIFERENCIAL EPR2A063030 2P-63A-30mA (MAXGE) | F31: UND | G31: 2 | H31: si | I31: 46058 | J31: 1 | K31: =+G31-J31 -> 1
A32: 28 | B32: 16 | C32: 48 | D32: 281 | E32: PORTA FUSIBLE SGF-32-DC (MAXGE) | F32: UND | G32: 4 | H32: si | K32: =+G32-J32 -> 4
A33: 29 | B33: 16 | C33: 49 | D33: 282 | E33: CONTACTOR MODULAR RV32 (REVALCO) | F33: UND | G33: 1 | H33: si | K33: =+G33-J33 -> 1
A34: 30 | B34: 16 | C34: 50 | D34: 283 | E34: FUSIBLE 32A-1000VDC (SASSIN) | F34: UND | G34: 10 | H34: si | I34: 46058 | J34: 6 | K34: =+G34-J34 -> 4
A35: 31 | B35: 16 | C35: 51 | D35: 284 | E35: LIMITADOR MONOFASICO 3SUR1 15/30kA-275V (SASSIN) | F35: UND | G35: 1 | H35: si | K35: =+G35-J35 -> 1
A36: 32 | B36: 16 | C36: 52 | D36: 285 | E36: TERMICO EPBE63M1NC63 1P+N C63 (MAXGE) | F36: UND | G36: 2 | H36: si | I36: 46058 | J36: 1 | K36: =+G36-J36 -> 1

Sheet HECTOR-JAVI 06FEB
A1: FMT-03-ALM | C1: FORMATO ALISTAMIENTO DE MATERIALES (ALMACENISTA) | G1: CONSEC. # | I1: 2 | K1: REGISTRO | L1: OK
A2: CLIENTE | C2: ILDEFONSO MONILLAS CAMPAN | G2: PARTE TRAB. # | I2: 4 | K2: DEVOLUCION | L2: OK
A3: CIUDAD | C3: Mancha Real | F3: ALISTADO POR: FABIO GUTIERREZ | G3: FECHA REQUER. | I3: 46059
A4: CUADIRILLA FORMADA POR: | F4: HECTOR - JAVI
A5: LINEA | B5: CODIGO | F5: DESCRIPCION | G5: UND MED. | H5: CANT. | I5: VERIFICA TECNICO | J5: FECHA | K5: DEVOLUC. | L5: CANT. REAL CONSUMIDA | M5: SERIAL Nª
A6: 1 | B6: 13 | C6: 21 | D6: 181 | E6: =CONCATENATE(B6,"-",C6,"-",D6) -> 13-21-181 | F6: =IFERROR(VLOOKUP(E6,'LISTA ITEMS (2)'!$E$2:$G$910,2,FALSE)," ") -> TACO P/BRIDA NEGRO | G6: =IFERROR(VLOOKUP(E6,'LISTA ITEMS (2)'!$E$2:$G$910,3,FALSE)," ") -> UND | H6: 100 | I6: si | J6: 46062 | K6: 100 | L6: =+H6-K6 -> 0
A7: 2 | B7: 13 | C7: 22 | D7: 183 | E7: =CONCATENATE(B7,"-",C7,"-",D7) -> 13-22-183 | F7: =IFERROR(VLOOKUP(E7,'LISTA ITEMS (2)'!$E$2:$G$910,2,FALSE)," ") -> BRIDA P/INTERIOR NEGRA | G7: =IFERROR(VLOOKUP(E7,'LISTA ITEMS (2)'!$E$2:$G$910,3,FALSE)," ") -> UND | H7: 100 | I7: si | J7: 46062 | K7: 100 | L7: =+H7-K7 -> 0
A8: 3 | B8: 13 | C8: 22 | D8: 184 | E8: =CONCATENATE(B8,"-",C8,"-",D8) -> 13-22-184 | F8: =IFERROR(VLOOKUP(E8,'LISTA ITEMS (2)'!$E$2:$G$910,2,FALSE)," ") -> BRIDA P/EXTERIOR NEGRA | G8: =IFERROR(VLOOKUP(E8,'LISTA ITEMS (2)'!$E$2:$G$910,3,FALSE)," ") -> UND | H8: 50 | I8: si | J8: 46062 | K8: 50 | L8: =+H8-K8 -> 0
A9: 4 | B9: 10 | C9: 37 | D9: 232 | E9: =CONCATENATE(B9,"-",C9,"-",D9) -> 10-37-232 | F9: =IFERROR(VLOOKUP(E9,'LISTA ITEMS (2)'!$E$2:$G$910,2,FALSE)," ") -> SOPORTE CENTRAL NEGRO | G9: =IFERROR(VLOOKUP(E9,'LISTA ITEMS (2)'!$E$2:$G$910,3,FALSE)," ") -> UND | H9: 25 | I9: si | J9: 46062 | K9: 25 | L9: =+H9-K9 -> 0
A10: 5 | B10: 10 | C10: 37 | D10: 315 | E10: =CONCATENATE(B10,"-",C10,"-",D10) -> 10-37-315 | F10: =IFERROR(VLOOKUP(E10,'LISTA ITEMS (2)'!$E$2:$G$910,2,FALSE)," ") -> SOPORTE FINAL NEGRO | G10: =IFERROR(VLOOKUP(E10,'LISTA ITEMS (2)'!$E$2:$G$910,3,FALSE)," ") -> UND | H10: 25 | I10: si | J10: 46062 | K10: 25 | L10: =+H10-K10 -> 0
A11: 6 | B11: 6 | C11: 23 | D11: 192 | E11: =CONCATENATE(B11,"-",C11,"-",D11) -> 6-23-192 | F11: =IFERROR(VLOOKUP(E11,'LISTA ITEMS (2)'!$E$2:$G$910,2,FALSE)," ") -> CINTA ACERO PERFORADA PARA MONTAJE | G11: =IFERROR(VLOOKUP(E11,'LISTA ITEMS (2)'!$E$2:$G$910,3,FALSE)," ") -> UND | H11: 3 | I11: si | J11: 46062 | K11: 1.5 | L11: =+H11-K11 -> 1.5
A12: 7 | B12: 16 | C12: 45 | D12: 294 | E12: =CONCATENATE(B12,"-",C12,"-",D12) -> 16-45-294 | F12: =IFERROR(VLOOKUP(E12,'LISTA ITEMS (2)'!$E$2:$G$910,2,FALSE)," ") -> CAJA DE ESTANCA 133X180X80 EV161 (IDE) | G12: =IFERROR(VLOOKUP(E12,'LISTA ITEMS (2)'!$E$2:$G$910,3,FALSE)," ") -> UND | H12: 1 | I12: si | L12: =+H12-K12 -> 1
A13: 8 | B13: 10 | C13: 43 | D13: 270 | E13: =CONCATENATE(B13,"-",C13,"-",D13) -> 10-43-270 | F13: =IFERROR(VLOOKUP(E13,'LISTA ITEMS (2)'!$E$2:$G$910,2,FALSE)," ") -> EMPALME ALUMINIO P/BARRA | G13: =IFERROR(VLOOKUP(E13,'LISTA ITEMS (2)'!$E$2:$G$910,3,FALSE)," ") -> UND | H13: 8 | I13: si | J13: 46062 | K13: 8 | L13: =+H13-K13 -> 0
A14: 9 | B14: 16 | C14: 45 | D14: 276 | E14: =CONCATENATE(B14,"-",C14,"-",D14) -> 16-45-276 | F14: =IFERROR(VLOOKUP(E14,'LISTA ITEMS (2)'!$E$2:$G$910,2,FALSE)," ") -> CAJA ESTANCA (COCHERA) EXTERIOR 18PT (IDE) | G14: =IFERROR(VLOOKUP(E14,'LISTA ITEMS (2)'!$E$2:$G$910,3,FALSE)," ") -> UND | H14: 1 | I14: si | J14: 46062 | K14: 1 | L14: =+H14-K14 -> 0
A15: 10 | B15: 16 | C15: 45 | D15: 317 | E15: =CONCATENATE(B15,"-",C15,"-",D15) -> 16-45-317 | F15: =IFERROR(VLOOKUP(E15,'LISTA ITEMS (2)'!$E$2:$G$910,2,FALSE)," ") -> CAJA DISTRIBUCION INTERIOR 8 ELEM. (SOLERA) | G15: =IFERROR(VLOOKUP(E15,'LISTA ITEMS (2)'!$E$2:$G$910,3,FALSE)," ") -> UND | H15: 1 | I15: si | J15: 46062 | K15: 1 | L15: =+H15-K15 -> 0
A16: 11 | B16: 16 | C16: 47 | D16: 318 | E16: =CONCATENATE(B16,"-",C16,"-",D16) -> 16-47-318 | F16: =IFERROR(VLOOKUP(E16,'LISTA ITEMS (2)'!$E$2:$G$910,2,FALSE)," ") -> DIFERENCIAL EPR2A040030 2P-40A-30mA (MAXGE) | G16: =IFERROR(VLOOKUP(E16,'LISTA ITEMS (2)'!$E$2:$G$910,3,FALSE)," ") -> UND | H16: 1 | I16: si | L16: =+H16-K16 -> 1
A17: 12 | B17: 16 | C17: 52 | D17: 319 | E17: =CONCATENATE(B17,"-",C17,"-",D17) -> 16-52-319 | F17: =IFERROR(VLOOKUP(E17,'LISTA ITEMS (2)'!$E$2:$G$910,2,FALSE)," ") -> TERMICO EPBE63M1NC25 1P+N C25 (MAXGE) | G17: =IFERROR(VLOOKUP(E17,'LISTA ITEMS (2)'!$E$2:$G$910,3,FALSE)," ") -> UND | H17: 1 | I17: si | L17: =+H17-K17 -> 1
A18: 13 | B18: 16 | C18: 45 | D18: 275 | E18: =CONCATENATE(B18,"-",C18,"-",D18) -> 16-45-275 | F18: =IFERROR(VLOOKUP(E18,'LISTA ITEMS (2)'!$E$2:$G$910,2,FALSE)," ") -> CAJA DISTRIBUCION INTERIOR 18 ELEM. (SOLERA) | G18: =IFERROR(VLOOKUP(E18,'LISTA ITEMS (2)'!$E$2:$G$910,3,FALSE)," ") -> UND | H18: 1 | I18: si | J18: 46062 | K18: 1 | L18: =+H18-K18 -> 0
A19: 14 | B19: 16 | C19: 45 | D19: 299 | E19: =CONCATENATE(B19,"-",C19,"-",D19) -> 16-45-299 | F19: =IFERROR(VLOOKUP(E19,'LISTA ITEMS (2)'!$E$2:$G$910,2,FALSE)," ") -> CAJA ESTANCA (COCHERA) EXTERIOR 8PT (IDE) | G19: =IFERROR(VLOOKUP(E19,'LISTA ITEMS (2)'!$E$2:$G$910,3,FALSE)," ") -> UND | H19: 1 | I19: si | L19: =+H19-K19 -> 1
A20: 15 | B20: 10 | C20: 42 | D20: 268 | E20: =CONCATENATE(B20,"-",C20,"-",D20) -> 10-42-268 | F20: =IFERROR(VLOOKUP(E20,'LISTA ITEMS (2)'!$E$2:$G$910,2,FALSE)," ") -> PATA ALUMINIO PARA ESTRUCTURA PLACA SOLAR ANGULO 30º | G20: =IFERROR(VLOOKUP(E20,'LISTA ITEMS (2)'!$E$2:$G$910,3,FALSE)," ") -> UND | H20: 8 | I20: si | J20: 46062 | K20: 8 | L20: =+H20-K20 -> 0
A21: 16 | B21: 16 | C21: 31 | D21: 320 | E21: =CONCATENATE(B21,"-",C21,"-",D21) -> 16-31-320 | F21: =IFERROR(VLOOKUP(E21,'LISTA ITEMS (2)'!$E$2:$G$910,2,FALSE)," ") -> JUEGO CABLE PARA BATERIA DE LITIO B4850 | G21: =IFERROR(VLOOKUP(E21,'LISTA ITEMS (2)'!$E$2:$G$910,3,FALSE)," ") -> UND | H21: 1 | I21: si | L21: 1
A22: 17 | B22: 17 | C22: 44 | D22: 271 | E22: =CONCATENATE(B22,"-",C22,"-",D22) -> 17-44-271 | F22: =IFERROR(VLOOKUP(E22,'LISTA ITEMS (2)'!$E$2:$G$910,2,FALSE)," ") -> SELLANTE QUIMICO BLANCO | G22: =IFERROR(VLOOKUP(E22,'LISTA ITEMS (2)'!$E$2:$G$910,3,FALSE)," ") -> UND | H22: 1 | I22: si | J22: 46062 | K22: 1 | L22: =+H22-K22 -> 0
A23: 18 | B23: 17 | C23: 44 | D23: 272 | E23: =CONCATENATE(B23,"-",C23,"-",D23) -> 17-44-272 | F23: =IFERROR(VLOOKUP(E23,'LISTA ITEMS (2)'!$E$2:$G$910,2,FALSE)," ") -> SELLANTE QUIMICO GRIS | G23: =IFERROR(VLOOKUP(E23,'LISTA ITEMS (2)'!$E$2:$G$910,3,FALSE)," ") -> UND | H23: 1 | I23: si | J23: 46062 | K23: 1 | L23: =+H23-K23 -> 0
A24: 19 | B24: 8 | C24: 27 | D24: 321 | E24: =CONCATENATE(B24,"-",C24,"-",D24) -> 8-27-321 | F24: =IFERROR(VLOOKUP(E24,'LISTA ITEMS (2)'!$E$2:$G$910,2,FALSE)," ") -> TORNILLO AUTOTALADRANTE CON C/HEXAGONAL - R/PARCIAL - ARANDELA CAUCHO 6X120mm A/GALV. | G24: =IFERROR(VLOOKUP(E24,'LISTA ITEMS (2)'!$E$2:$G$910,3,FALSE)," ") -> UND | H24: 20 | I24: si | J24: 46062 | K24: 20 | L24: =+H24-K24 -> 0
A25: 20 | B25: 16 | C25: 59 | D25: 322 | E25: =CONCATENATE(B25,"-",C25,"-",D25) -> 16-59-322 | F25: =IFERROR(VLOOKUP(E25,'LISTA ITEMS (2)'!$E$2:$G$910,2,FALSE)," ") -> CLAVIJA CAUCHO NEGRA 10/16A | G25: =IFERROR(VLOOKUP(E25,'LISTA ITEMS (2)'!$E$2:$G$910,3,FALSE)," ") -> UND | H25: 1 | I25: si | L25: =+H25-K25 -> 1
A26: 21 | B26: 9 | C26: 2 | D26: 291 | E26: =CONCATENATE(B26,"-",C26,"-",D26) -> 9-2-291 | F26: =IFERROR(VLOOKUP(E26,'LISTA ITEMS (2)'!$E$2:$G$910,2,FALSE)," ") -> TUBO ELECTRICO PVC 25mm - 3mt(AISCAN) | G26: =IFERROR(VLOOKUP(E26,'LISTA ITEMS (2)'!$E$2:$G$910,3,FALSE)," ") -> UND | H26: 8 | I26: si | J26: 46062 | K26: 6 | L26: =+H26-K26 -> 2
A27: 22 | B27: 10 | C27: 15 | D27: 269 | E27: =CONCATENATE(B27,"-",C27,"-",D27) -> 10-15-269 | F27: =IFERROR(VLOOKUP(E27,'LISTA ITEMS (2)'!$E$2:$G$910,2,FALSE)," ") -> BARRA ALUMINIO PARA ESTRUCTURA 3.60mt | G27: =IFERROR(VLOOKUP(E27,'LISTA ITEMS (2)'!$E$2:$G$910,3,FALSE)," ") -> UND | H27: 10 | I27: si | L27: =+H27-K27 -> 10
A28: 23 | B28: 7 | C28: 38 | D28: 247 | E28: =CONCATENATE(B28,"-",C28,"-",D28) -> 7-38-247 | F28: =IFERROR(VLOOKUP(E28,'LISTA ITEMS (2)'!$E$2:$G$910,2,FALSE)," ") -> PLACA SOLAR JAM60D42-535LB 535W / 44.13V | G28: =IFERROR(VLOOKUP(E28,'LISTA ITEMS (2)'!$E$2:$G$910,3,FALSE)," ") -> UND | H28: 8 | I28: si | J28: 46062 | K28: 8 | L28: =+H28-K28 -> 0
A29: 24 | B29: 7 | C29: 54 | D29: 323 | E29: =CONCATENATE(B29,"-",C29,"-",D29) -> 7-54-323 | F29: =IFERROR(VLOOKUP(E29,'LISTA ITEMS (2)'!$E$2:$G$910,2,FALSE)," ") -> BATERIA LPF LITHIUM B3 (DYNESS) | G29: =IFERROR(VLOOKUP(E29,'LISTA ITEMS (2)'!$E$2:$G$910,3,FALSE)," ") -> UND | H29: 3 | I29: si | L29: =+H29-K29 -> 3 | M29: 14031612302260443 14031612302260454 14031612302260445
A30: 25 | B30: 14 | C30: 24 | D30: 193 | E30: =CONCATENATE(B30,"-",C30,"-",D30) -> 14-24-193 | F30: =IFERROR(VLOOKUP(E30,'LISTA ITEMS (2)'!$E$2:$G$910,2,FALSE)," ") -> DISCO CORTE ACERO/INOX A1 2EN1 | G30: =IFERROR(VLOOKUP(E30,'LISTA ITEMS (2)'!$E$2:$G$910,3,FALSE)," ") -> UND | H30: 3 | I30: si | J30: 46062 | K30: 1 | L30: =+H30-K30 -> 2
A31: 26 | B31: 16 | C31: 60 | D31: 324 | E31: =CONCATENATE(B31,"-",C31,"-",D31) -> 16-60-324 | F31: =IFERROR(VLOOKUP(E31,'LISTA ITEMS (2)'!$E$2:$G$910,2,FALSE)," ") -> REGLETA CONEXIÓN ELECTRICA 35mm NEGRA 12Puntos | G31: =IFERROR(VLOOKUP(E31,'LISTA ITEMS (2)'!$E$2:$G$910,3,FALSE)," ") -> UND | H31: 1 | I31: si | L31: =+H31-K31 -> 1
A32: 27 | B32: 16 | C32: 60 | D32: 325 | E32: =CONCATENATE(B32,"-",C32,"-",D32) -> 16-60-325 | F32: =IFERROR(VLOOKUP(E32,'LISTA ITEMS (2)'!$E$2:$G$910,2,FALSE)," ") -> REGLETA CONEXIÓN ELECTRICA 16mm NEGRA | G32: =IFERROR(VLOOKUP(E32,'LISTA ITEMS (2)'!$E$2:$G$910,3,FALSE)," ") -> UND | H32: 1 | I32: si | L32: =+H32-K32 -> 1
A33: 28 | B33: 3 | C33: 31 | D33: 277 | E33: =CONCATENATE(B33,"-",C33,"-",D33) -> 3-31-277 | F33: =IFERROR(VLOOKUP(E33,'LISTA ITEMS (2)'!$E$2:$G$910,2,FALSE)," ") -> CABLE Nª 6 P/PLACA SOLAR NEGRO | G33: =IFERROR(VLOOKUP(E33,'LISTA ITEMS (2)'!$E$2:$G$910,3,FALSE)," ") -> MT | H33: 15 | I33: si | J33: 46062 | K33: 15 | L33: =+H33-K33 -> 0
A34: 29 | B34: 3 | C34: 31 | D34: 278 | E34: =CONCATENATE(B34,"-",C34,"-",D34) -> 3-31-278 | F34: =IFERROR(VLOOKUP(E34,'LISTA ITEMS (2)'!$E$2:$G$910,2,FALSE)," ") -> CABLE Nª 6 P/PLACA SOLAR ROJO | G34: =IFERROR(VLOOKUP(E34,'LISTA ITEMS (2)'!$E$2:$G$910,3,FALSE)," ") -> MT | H34: 15 | I34: si | J34: 46062 | K34: 15 | L34: =+H34-K34 -> 0
A35: 30 | B35: 4 | C35: 15 | D35: 326 | E35: =CONCATENATE(B35,"-",C35,"-",D35) -> 4-15-326 | F35: =IFERROR(VLOOKUP(E35,'LISTA ITEMS (2)'!$E$2:$G$910,2,FALSE)," ") -> BARRA PERFORADA PARA REFUERZO 27x18x2MT GALV. | G35: =IFERROR(VLOOKUP(E35,'LISTA ITEMS (2)'!$E$2:$G$910,3,FALSE)," ") -> UND | H35: 6 | I35: si | J35: 46062 | K35: 6 | L35: =+H35-K35 -> 0
A36: 31 | B36: 7 | C36: 35 | D36: 327 | E36: =CONCATENATE(B36,"-",C36,"-",D36) -> 7-35-327 | F36: =IFERROR(VLOOKUP(E36,'LISTA ITEMS (2)'!$E$2:$G$910,2,FALSE)," ") -> INVERSOR 48/5000/70-50-230V MULTIPLUS (VICTROM ENERGY) | G36: =IFERROR(VLOOKUP(E36,'LISTA ITEMS (2)'!$E$2:$G$910,3,FALSE)," ") -> UND | H36: 1 | I36: si | J36: 46062 | K36: 1 | L36: =+H36-K36 -> 0 | M36: HQ2424266C3
A37: 32 | B37: 7 | C37: 36 | D37: 231 | E37: =CONCATENATE(B37,"-",C37,"-",D37) -> 7-36-231 | F37: =IFERROR(VLOOKUP(E37,'LISTA ITEMS (2)'!$E$2:$G$910,2,FALSE)," ") -> CONTROLADOR SMART SOLAR MPPT 250/100-TR VICTROM ENERGY | G37: =IFERROR(VLOOKUP(E37,'LISTA ITEMS (2)'!$E$2:$G$910,3,FALSE)," ") -> UND | H37: 1 | I37: si | L37: =+H37-K37 -> 1 | M37: HQ2505PP6CN
A38: 33 | E38: =CONCATENATE(B38,"-",C38,"-",D38) -> -- | F38: =IFERROR(VLOOKUP(E38,'LISTA ITEMS (2)'!$E$2:$G$910,2,FALSE)," ") -> 0 | G38: =IFERROR(VLOOKUP(E38,'LISTA ITEMS (2)'!$E$2:$G$910,3,FALSE)," ") -> 0
A40: NOTA: TODO EL MATERIAL FUE REVISADO POR LOS TECNICOS JAVI Y HECTOR.

Sheet SALI FEBRE 2026
A1: ALM-07-SAL | G1: RELACION DETALLA DE SALIDAS DIARIAS
A2: LINEA | B2: # FORMT. ALISTAM. | C2: PARTE TRABAJO # | D2: UNIDAD DE NEGOCIO | E2: TIPO DE TRABAJO | F2: CLEINTE | G2: CIUDAD | H2: TECNICOS RESPONSABLE | I2: FECHA DE CARGUE | J2: GRUPO | K2: ELEM | L2: ITEM | M2: CODIGO | N2: DESCRIPCION | O2: UND MEDIDA | P2: CANT. ENTREGADA | Q2: NOTA | R2: SERIAL | S2: CANT. DEVOLUC.
A3: 1 | B3: 1 | C3: 2 | F3: JESUS MORALES BUSTOS | G3: JAEN | H3: HECTOR Y MANUEL | I3: 46055 | J3: 13 | K3: 22 | L3: 184 | M3: =CONCATENATE(J3,"-",K3,"-",L3) -> 13-22-184 | N3: =IFERROR(VLOOKUP(M3,'LISTA ITEMS (2)'!$E$2:$G$910,2,FALSE)," ") -> BRIDA P/EXTERIOR NEGRA | O3: =IFERROR(VLOOKUP(M3,'LISTA ITEMS (2)'!$E$2:$G$910,3,FALSE)," ") -> UND | P3: 100 | Q3: INSTALACION DE INTERCAMBIADOR SPE 10KW | S3: 50
A4: 2 | B4: 1 | C4: 2 | F4: JESUS MORALES BUSTOS | G4: JAEN | H4: HECTOR Y MANUEL | I4: 46055 | J4: 6 | K4: 23 | L4: 192 | M4: =CONCATENATE(J4,"-",K4,"-",L4) -> 6-23-192 | N4: =IFERROR(VLOOKUP(M4,'LISTA ITEMS (2)'!$E$2:$G$910,2,FALSE)," ") -> CINTA ACERO PERFORADA PARA MONTAJE | O4: =IFERROR(VLOOKUP(M4,'LISTA ITEMS (2)'!$E$2:$G$910,3,FALSE)," ") -> UND | P4: 2 | Q4: INSTALACION DE INTERCAMBIADOR SPE 10KW | S4: 2
A5: 3 | B5: 1 | C5: 2 | F5: JESUS MORALES BUSTOS | G5: JAEN | H5: HECTOR Y MANUEL | I5: 46055 | J5: 14 | K5: 24 | L5: 193 | M5: =CONCATENATE(J5,"-",K5,"-",L5) -> 14-24-193 | N5: =IFERROR(VLOOKUP(M5,'LISTA ITEMS (2)'!$E$2:$G$910,2,FALSE)," ") -> DISCO CORTE ACERO/INOX A1 2EN1 | O5: =IFERROR(VLOOKUP(M5,'LISTA ITEMS (2)'!$E$2:$G$910,3,FALSE)," ") -> UND | P5: 1 | Q5: INSTALACION DE INTERCAMBIADOR SPE 10KW | S5: 1
A6: 4 | B6: 1 | C6: 2 | F6: JESUS MORALES BUSTOS | G6: JAEN | H6: HECTOR Y MANUEL | I6: 46055 | J6: 3 | K6: 31 | L6: 209 | M6: =CONCATENATE(J6,"-",K6,"-",L6) -> 3-31-209 | N6: =IFERROR(VLOOKUP(M6,'LISTA ITEMS (2)'!$E$2:$G$910,2,FALSE)," ") -> CABLE Nª 6 C/ALTERNA MARRON | O6: =IFERROR(VLOOKUP(M6,'LISTA ITEMS (2)'!$E$2:$G$910,3,FALSE)," ") -> MT | P6: 100 | Q6: INSTALACION DE INTERCAMBIADOR SPE 10KW | S6: 100
A7: 5 | B7: 1 | C7: 2 | F7: JESUS MORALES BUSTOS | G7: JAEN | H7: HECTOR Y MANUEL | I7: 46055 | J7: 3 | K7: 31 | L7: 210 | M7: =CONCATENATE(J7,"-",K7,"-",L7) -> 3-31-210 | N7: =IFERROR(VLOOKUP(M7,'LISTA ITEMS (2)'!$E$2:$G$910,2,FALSE)," ") -> CABLE Nª 6 C/ALTERNA GRIS | O7: =IFERROR(VLOOKUP(M7,'LISTA ITEMS (2)'!$E$2:$G$910,3,FALSE)," ") -> MT | P7: 100 | Q7: INSTALACION DE INTERCAMBIADOR SPE 10KW | S7: 100
A8: 6 | B8: 1 | C8: 2 | F8: JESUS MORALES BUSTOS | G8: JAEN | H8: HECTOR Y MANUEL | I8: 46055 | J8: 3 | K8: 31 | L8: 212 | M8: =CONCATENATE(J8,"-",K8,"-",L8) -> 3-31-212 | N8: =IFERROR(VLOOKUP(M8,'LISTA ITEMS (2)'!$E$2:$G$910,2,FALSE)," ") -> CABLE Nª 6 C/ALTERNA AZUL | O8: =IFERROR(VLOOKUP(M8,'LISTA ITEMS (2)'!$E$2:$G$910,3,FALSE)," ") -> MT | P8: 100 | Q8: INSTALACION DE INTERCAMBIADOR SPE 10KW | S8: 100
A9: 7 | B9: 1 | C9: 2 | F9: JESUS MORALES BUSTOS | G9: JAEN | H9: HECTOR Y MANUEL | I9: 46055 | J9: 3 | K9: 31 | L9: 213 | M9: =CONCATENATE(J9,"-",K9,"-",L9) -> 3-31-213 | N9: =IFERROR(VLOOKUP(M9,'LISTA ITEMS (2)'!$E$2:$G$910,2,FALSE)," ") -> CABLE Nª 6 C/ALTERNA NEGRO | O9: =IFERROR(VLOOKUP(M9,'LISTA ITEMS (2)'!$E$2:$G$910,3,FALSE)," ") -> MT | P9: 100 | Q9: INSTALACION DE INTERCAMBIADOR SPE 10KW | S9: 100
A10: 8 | B10: 1 | C10: 2 | F10: JESUS MORALES BUSTOS | G10: JAEN | H10: HECTOR Y MANUEL | I10: 46055 | J10: 9 | K10: 32 | L10: 223 | M10: =CONCATENATE(J10,"-",K10,"-",L10) -> 9-32-223 | N10: =IFERROR(VLOOKUP(M10,'LISTA ITEMS (2)'!$E$2:$G$910,2,FALSE)," ") -> CURVA PVC M-25 GRIS TIPO A | O10: =IFERROR(VLOOKUP(M10,'LISTA ITEMS (2)'!$E$2:$G$910,3,FALSE)," ") -> UND | P10: =20*3 -> 60 | Q10: INSTALACION DE INTERCAMBIADOR SPE 10KW | S10: 22
A11: 9 | B11: 1 | C11: 2 | F11: JESUS MORALES BUSTOS | G11: JAEN | H11: HECTOR Y MANUEL | I11: 46055 | J11: 4 | K11: 15 | L11: 267 | M11: =CONCATENATE(J11,"-",K11,"-",L11) -> 4-15-267 | N11: =IFERROR(VLOOKUP(M11,'LISTA ITEMS (2)'!$E$2:$G$910,2,FALSE)," ") -> BARRA PERFORADA PARA REFUERZO 20X10X2MT GALV. | O11: =IFERROR(VLOOKUP(M11,'LISTA ITEMS (2)'!$E$2:$G$910,3,FALSE)," ") -> UND | P11: 30 | Q11: INSTALACION DE INTERCAMBIADOR SPE 10KW
A12: 10 | B12: 1 | C12: 2 | F12: JESUS MORALES BUSTOS | G12: JAEN | H12: HECTOR Y MANUEL | I12: 46055 | J12: 10 | K12: 42 | L12: 268 | M12: =CONCATENATE(J12,"-",K12,"-",L12) -> 10-42-268 | N12: =IFERROR(VLOOKUP(M12,'LISTA ITEMS (2)'!$E$2:$G$910,2,FALSE)," ") -> PATA ALUMINIO PARA ESTRUCTURA PLACA SOLAR ANGULO 30º | O12: =IFERROR(VLOOKUP(M12,'LISTA ITEMS (2)'!$E$2:$G$910,3,FALSE)," ") -> UND | P12: 20 | Q12: INSTALACION DE INTERCAMBIADOR SPE 10KW | S12: 10
A13: 11 | B13: 1 | C13: 2 | F13: JESUS MORALES BUSTOS | G13: JAEN | H13: HECTOR Y MANUEL | I13: 46055 | J13: 10 | K13: 15 | L13: 269 | M13: =CONCATENATE(J13,"-",K13,"-",L13) -> 10-15-269 | N13: =IFERROR(VLOOKUP(M13,'LISTA ITEMS (2)'!$E$2:$G$910,2,FALSE)," ") -> BARRA ALUMINIO PARA ESTRUCTURA 3.60mt | O13: =IFERROR(VLOOKUP(M13,'LISTA ITEMS (2)'!$E$2:$G$910,3,FALSE)," ") -> UND | P13: 20 | Q13: INSTALACION DE INTERCAMBIADOR SPE 10KW
A14: 12 | B14: 1 | C14: 2 | F14: JESUS MORALES BUSTOS | G14: JAEN | H14: HECTOR Y MANUEL | I14: 46055 | J14: 13 | K14: 25 | L14: 255 | M14: =CONCATENATE(J14,"-",K14,"-",L14) -> 13-25-255 | N14: =IFERROR(VLOOKUP(M14,'LISTA ITEMS (2)'!$E$2:$G$910,2,FALSE)," ") -> ANCLAJE PLASTICO MULTIUSO C/COLLARIN 10X61MM | O14: =IFERROR(VLOOKUP(M14,'LISTA ITEMS (2)'!$E$2:$G$910,3,FALSE)," ") -> UND | P14: 50 | Q14: INSTALACION DE INTERCAMBIADOR SPE 10KW | S14: 50
A15: 13 | B15: 1 | C15: 2 | F15: JESUS MORALES BUSTOS | G15: JAEN | H15: HECTOR Y MANUEL | I15: 46055 | J15: 10 | K15: 43 | L15: 270 | M15: =CONCATENATE(J15,"-",K15,"-",L15) -> 10-43-270 | N15: =IFERROR(VLOOKUP(M15,'LISTA ITEMS (2)'!$E$2:$G$910,2,FALSE)," ") -> EMPALME ALUMINIO P/BARRA | O15: =IFERROR(VLOOKUP(M15,'LISTA ITEMS (2)'!$E$2:$G$910,3,FALSE)," ") -> UND | P15: 15 | Q15: INSTALACION DE INTERCAMBIADOR SPE 10KW | S15: 15
A16: 14 | B16: 1 | C16: 2 | F16: JESUS MORALES BUSTOS | G16: JAEN | H16: HECTOR Y MANUEL | I16: 46055 | J16: 17 | K16: 44 | L16: 271 | M16: =CONCATENATE(J16,"-",K16,"-",L16) -> 17-44-271 | N16: =IFERROR(VLOOKUP(M16,'LISTA ITEMS (2)'!$E$2:$G$910,2,FALSE)," ") -> SELLANTE QUIMICO BLANCO | O16: =IFERROR(VLOOKUP(M16,'LISTA ITEMS (2)'!$E$2:$G$910,3,FALSE)," ") -> UND | P16: 1 | Q16: INSTALACION DE INTERCAMBIADOR SPE 10KW | S16: 2
A17: 15 | B17: 1 | C17: 2 | F17: JESUS MORALES BUSTOS | G17: JAEN | H17: HECTOR Y MANUEL | I17: 46055 | J17: 17 | K17: 44 | L17: 272 | M17: =CONCATENATE(J17,"-",K17,"-",L17) -> 17-44-272 | N17: =IFERROR(VLOOKUP(M17,'LISTA ITEMS (2)'!$E$2:$G$910,2,FALSE)," ") -> SELLANTE QUIMICO GRIS | O17: =IFERROR(VLOOKUP(M17,'LISTA ITEMS (2)'!$E$2:$G$910,3,FALSE)," ") -> UND | P17: 1 | Q17: INSTALACION DE INTERCAMBIADOR SPE 10KW | S17: 0.5
A18: 16 | B18: 1 | C18: 2 | F18: JESUS MORALES BUSTOS | G18: JAEN | H18: HECTOR Y MANUEL | I18: 46055 | J18: 7 | K18: 35 | L18: 274 | M18: =CONCATENATE(J18,"-",K18,"-",L18) -> 7-35-274 | N18: =IFERROR(VLOOKUP(M18,'LISTA ITEMS (2)'!$E$2:$G$910,2,FALSE)," ") -> INVERSOR HIBRIDO MONOFASICO SPE 10000ES 10KW BATER. BAJO VOLTAJE Y BACKUP INCORP. (GROWATT) | O18: =IFERROR(VLOOKUP(M18,'LISTA ITEMS (2)'!$E$2:$G$910,3,FALSE)," ") -> UND | P18: 1 | Q18: INSTALACION DE INTERCAMBIADOR SPE 10KW S/N HAQ1F4P4JV
A19: 17 | B19: 1 | C19: 2 | F19: JESUS MORALES BUSTOS | G19: JAEN | H19: HECTOR Y MANUEL | I19: 46055 | J19: 16 | K19: 45 | L19: 275 | M19: =CONCATENATE(J19,"-",K19,"-",L19) -> 16-45-275 | N19: =IFERROR(VLOOKUP(M19,'LISTA ITEMS (2)'!$E$2:$G$910,2,FALSE)," ") -> CAJA DISTRIBUCION INTERIOR 18 ELEM. (SOLERA) | O19: =IFERROR(VLOOKUP(M19,'LISTA ITEMS (2)'!$E$2:$G$910,3,FALSE)," ") -> UND | P19: 1 | Q19: INSTALACION DE INTERCAMBIADOR SPE 10KW S/N HAQ1F4P4JV
A20: 18 | B20: 1 | C20: 2 | F20: JESUS MORALES BUSTOS | G20: JAEN | H20: HECTOR Y MANUEL | I20: 46055 | J20: 16 | K20: 45 | L20: 276 | M20: =CONCATENATE(J20,"-",K20,"-",L20) -> 16-45-276 | N20: =IFERROR(VLOOKUP(M20,'LISTA ITEMS (2)'!$E$2:$G$910,2,FALSE)," ") -> CAJA ESTANCA (COCHERA) EXTERIOR 18PT (IDE) | O20: =IFERROR(VLOOKUP(M20,'LISTA ITEMS (2)'!$E$2:$G$910,3,FALSE)," ") -> UND | P20: 1 | Q20: INSTALACION DE INTERCAMBIADOR SPE 10KW S/N HAQ1F4P4JV
A21: 19 | B21: 1 | C21: 2 | F21: JESUS MORALES BUSTOS | G21: JAEN | H21: HECTOR Y MANUEL | I21: 46055 | J21: 3 | K21: 31 | L21: 277 | M21: =CONCATENATE(J21,"-",K21,"-",L21) -> 3-31-277 | N21: =IFERROR(VLOOKUP(M21,'LISTA ITEMS (2)'!$E$2:$G$910,2,FALSE)," ") -> CABLE Nª 6 P/PLACA SOLAR NEGRO | O21: =IFERROR(VLOOKUP(M21,'LISTA ITEMS (2)'!$E$2:$G$910,3,FALSE)," ") -> MT | P21: 30 | Q21: INSTALACION DE INTERCAMBIADOR SPE 10KW S/N HAQ1F4P4JV
A22: 20 | B22: 1 | C22: 2 | F22: JESUS MORALES BUSTOS | G22: JAEN | H22: HECTOR Y MANUEL | I22: 46055 | J22: 3 | K22: 31 | L22: 278 | M22: =CONCATENATE(J22,"-",K22,"-",L22) -> 3-31-278 | N22: =IFERROR(VLOOKUP(M22,'LISTA ITEMS (2)'!$E$2:$G$910,2,FALSE)," ") -> CABLE Nª 6 P/PLACA SOLAR ROJO | O22: =IFERROR(VLOOKUP(M22,'LISTA ITEMS (2)'!$E$2:$G$910,3,FALSE)," ") -> MT | P22: 30 | Q22: INSTALACION DE INTERCAMBIADOR SPE 10KW S/N HAQ1F4P4JV
A23: 21 | B23: 1 | C23: 2 | F23: JESUS MORALES BUSTOS | G23: JAEN | H23: HECTOR Y MANUEL | I23: 46055 | J23: 16 | K23: 46 | L23: 279 | M23: =CONCATENATE(J23,"-",K23,"-",L23) -> 16-46-279 | N23: =IFERROR(VLOOKUP(M23,'LISTA ITEMS (2)'!$E$2:$G$910,2,FALSE)," ") -> MANGUERA CORRUGADA 25mm NEGRA | O23: =IFERROR(VLOOKUP(M23,'LISTA ITEMS (2)'!$E$2:$G$910,3,FALSE)," ") -> MT | P23: 1 | Q23: INSTALACION DE INTERCAMBIADOR SPE 10KW S/N HAQ1F4P4JV | S23: 1
A24: 22 | B24: 1 | C24: 2 | F24: JESUS MORALES BUSTOS | G24: JAEN | H24: HECTOR Y MANUEL | I24: 46055 | J24: 3 | K24: 31 | L24: 222 | M24: =CONCATENATE(J24,"-",K24,"-",L24) -> 3-31-222 | N24: =IFERROR(VLOOKUP(M24,'LISTA ITEMS (2)'!$E$2:$G$910,2,FALSE)," ") -> CABLE Nª 10 C/ALTERNA NEGRO | O24: =IFERROR(VLOOKUP(M24,'LISTA ITEMS (2)'!$E$2:$G$910,3,FALSE)," ") -> MT | P24: 100 | Q24: INSTALACION DE INTERCAMBIADOR SPE 10KW S/N HAQ1F4P4JV | S24: 88
A25: 23 | B25: 1 | C25: 2 | F25: JESUS MORALES BUSTOS | G25: JAEN | H25: HECTOR Y MANUEL | I25: 46055 | J25: 3 | K25: 31 | L25: 221 | M25: =CONCATENATE(J25,"-",K25,"-",L25) -> 3-31-221 | N25: =IFERROR(VLOOKUP(M25,'LISTA ITEMS (2)'!$E$2:$G$910,2,FALSE)," ") -> CABLE Nª 10 C/ALTERNA AZUL | O25: =IFERROR(VLOOKUP(M25,'LISTA ITEMS (2)'!$E$2:$G$910,3,FALSE)," ") -> MT | P25: 100 | Q25: INSTALACION DE INTERCAMBIADOR SPE 10KW S/N HAQ1F4P4JV | S25: 88
A26: 24 | B26: 1 | C26: 2 | F26: JESUS MORALES BUSTOS | G26: JAEN | H26: HECTOR Y MANUEL | I26: 46055 | J26: 3 | K26: 31 | L26: 220 | M26: =CONCATENATE(J26,"-",K26,"-",L26) -> 3-31-220 | N26: =IFERROR(VLOOKUP(M26,'LISTA ITEMS (2)'!$E$2:$G$910,2,FALSE)," ") -> CABLE Nª 10 C/ALTERNA GRIS | O26: =IFERROR(VLOOKUP(M26,'LISTA ITEMS (2)'!$E$2:$G$910,3,FALSE)," ") -> MT | P26: 100 | Q26: INSTALACION DE INTERCAMBIADOR SPE 10KW S/N HAQ1F4P4JV | S26: 88
A27: 25 | B27: 1 | C27: 2 | F27: JESUS MORALES BUSTOS | G27: JAEN | H27: HECTOR Y MANUEL | I27: 46055 | J27: 3 | K27: 31 | L27: 219 | M27: =CONCATENATE(J27,"-",K27,"-",L27) -> 3-31-219 | N27: =IFERROR(VLOOKUP(M27,'LISTA ITEMS (2)'!$E$2:$G$910,2,FALSE)," ") -> CABLE Nª 10 C/ALTERNA MARRON | O27: =IFERROR(VLOOKUP(M27,'LISTA ITEMS (2)'!$E$2:$G$910,3,FALSE)," ") -> MT | P27: 100 | Q27: INSTALACION DE INTERCAMBIADOR SPE 10KW S/N HAQ1F4P4JV | S27: 88
A28: 26 | B28: 1 | C28: 2 | F28: JESUS MORALES BUSTOS | G28: JAEN | H28: HECTOR Y MANUEL | I28: 46055 | J28: 3 | K28: 31 | L28: 218 | M28: =CONCATENATE(J28,"-",K28,"-",L28) -> 3-31-218 | N28: =IFERROR(VLOOKUP(M28,'LISTA ITEMS (2)'!$E$2:$G$910,2,FALSE)," ") -> CABLE Nª 10 C/ALTERNA VERDE/AMARILLO | O28: =IFERROR(VLOOKUP(M28,'LISTA ITEMS (2)'!$E$2:$G$910,3,FALSE)," ") -> MT | P28: 60 | Q28: INSTALACION DE INTERCAMBIADOR SPE 10KW S/N HAQ1F4P4JV | S28: 88
A29: 27 | B29: 1 | C29: 2 | F29: JESUS MORALES BUSTOS | G29: JAEN | H29: HECTOR Y MANUEL | I29: 46055 | J29: 16 | K29: 47 | L29: 280 | M29: =CONCATENATE(J29,"-",K29,"-",L29) -> 16-47-280 | N29: =IFERROR(VLOOKUP(M29,'LISTA ITEMS (2)'!$E$2:$G$910,2,FALSE)," ") -> DIFERENCIAL EPR2A063030 2P-63A-30mA (MAXGE) | O29: =IFERROR(VLOOKUP(M29,'LISTA ITEMS (2)'!$E$2:$G$910,3,FALSE)," ") -> UND | P29: 2 | Q29: INSTALACION DE INTERCAMBIADOR SPE 10KW S/N HAQ1F4P4JV | S29: 1
A30: 28 | B30: 1 | C30: 2 | F30: JESUS MORALES BUSTOS | G30: JAEN | H30: HECTOR Y MANUEL | I30: 46055 | J30: 16 | K30: 48 | L30: 281 | M30: =CONCATENATE(J30,"-",K30,"-",L30) -> 16-48-281 | N30: =IFERROR(VLOOKUP(M30,'LISTA ITEMS (2)'!$E$2:$G$910,2,FALSE)," ") -> PORTA FUSIBLE SGF-32-DC (MAXGE) | O30: =IFERROR(VLOOKUP(M30,'LISTA ITEMS (2)'!$E$2:$G$910,3,FALSE)," ") -> UND | P30: 4 | Q30: INSTALACION DE INTERCAMBIADOR SPE 10KW S/N HAQ1F4P4JV
A31: 29 | B31: 1 | C31: 2 | F31: JESUS MORALES BUSTOS | G31: JAEN | H31: HECTOR Y MANUEL | I31: 46055 | J31: 16 | K31: 49 | L31: 282 | M31: =CONCATENATE(J31,"-",K31,"-",L31) -> 16-49-282 | N31: =IFERROR(VLOOKUP(M31,'LISTA ITEMS (2)'!$E$2:$G$910,2,FALSE)," ") -> CONTACTOR MODULAR RV32 (REVALCO) | O31: =IFERROR(VLOOKUP(M31,'LISTA ITEMS (2)'!$E$2:$G$910,3,FALSE)," ") -> UND | P31: 1 | Q31: INSTALACION DE INTERCAMBIADOR SPE 10KW S/N HAQ1F4P4JV
A32: 30 | B32: 1 | C32: 2 | F32: JESUS MORALES BUSTOS | G32: JAEN | H32: HECTOR Y MANUEL | I32: 46055 | J32: 16 | K32: 50 | L32: 283 | M32: =CONCATENATE(J32,"-",K32,"-",L32) -> 16-50-283 | N32: =IFERROR(VLOOKUP(M32,'LISTA ITEMS (2)'!$E$2:$G$910,2,FALSE)," ") -> FUSIBLE 32A-1000VDC (SASSIN) | O32: =IFERROR(VLOOKUP(M32,'LISTA ITEMS (2)'!$E$2:$G$910,3,FALSE)," ") -> UND | P32: 10 | Q32: INSTALACION DE INTERCAMBIADOR SPE 10KW S/N HAQ1F4P4JV | S32: 6
A33: 31 | B33: 1 | C33: 2 | F33: JESUS MORALES BUSTOS | G33: JAEN | H33: HECTOR Y MANUEL | I33: 46055 | J33: 16 | K33: 51 | L33: 284 | M33: =CONCATENATE(J33,"-",K33,"-",L33) -> 16-51-284 | N33: =IFERROR(VLOOKUP(M33,'LISTA ITEMS (2)'!$E$2:$G$910,2,FALSE)," ") -> LIMITADOR MONOFASICO 3SU1 15/30kA-275V (SASSIN) | O33: =IFERROR(VLOOKUP(M33,'LISTA ITEMS (2)'!$E$2:$G$910,3,FALSE)," ") -> UND | P33: 1 | Q33: INSTALACION DE INTERCAMBIADOR SPE 10KW S/N HAQ1F4P4JV
A34: 32 | B34: 1 | C34: 2 | F34: JESUS MORALES BUSTOS | G34: JAEN | H34: HECTOR Y MANUEL | I34: 46055 | J34: 16 | K34: 52 | L34: 285 | M34: =CONCATENATE(J34,"-",K34,"-",L34) -> 16-52-285 | N34: =IFERROR(VLOOKUP(M34,'LISTA ITEMS (2)'!$E$2:$G$910,2,FALSE)," ") -> TERMICO EPBE63M1NC63 1P+N C63 (MAXGE) | O34: =IFERROR(VLOOKUP(M34,'LISTA ITEMS (2)'!$E$2:$G$910,3,FALSE)," ") -> UND | P34: 2 | Q34: INSTALACION DE INTERCAMBIADOR SPE 10KW S/N HAQ1F4P4JV | S34: 1
A35: 33 | B35: 2 | C35: 4 | F35: ILDEFONSO MONILLAS CAMPAN | G35: MANCHA REAL | H35: HECTOR Y JAVI | I35: 46179 | J35: 13 | K35: 21 | L35: 181 | M35: =CONCATENATE(J35,"-",K35,"-",L35) -> 13-21-181 | N35: =IFERROR(VLOOKUP(M35,'LISTA ITEMS (2)'!$E$2:$G$910,2,FALSE)," ") -> TACO P/BRIDA NEGRO | O35: =IFERROR(VLOOKUP(M35,'LISTA ITEMS (2)'!$E$2:$G$910,3,FALSE)," ") -> UND | P35: 100 | Q35: INSTALACION DE 8 PLACAS | S35: 100
A36: 34 | B36: 2 | C36: 4 | F36: ILDEFONSO MONILLAS CAMPAN | G36: MANCHA REAL | H36: HECTOR Y JAVI | I36: 46179 | J36: 13 | K36: 22 | L36: 183 | M36: =CONCATENATE(J36,"-",K36,"-",L36) -> 13-22-183 | N36: =IFERROR(VLOOKUP(M36,'LISTA ITEMS (2)'!$E$2:$G$910,2,FALSE)," ") -> BRIDA P/INTERIOR NEGRA | O36: =IFERROR(VLOOKUP(M36,'LISTA ITEMS (2)'!$E$2:$G$910,3,FALSE)," ") -> UND | P36: 100 | Q36: INSTALACION DE 8 PLACAS | S36: 100
A37: 35 | B37: 2 | C37: 4 | F37: ILDEFONSO MONILLAS CAMPAN | G37: MANCHA REAL | H37: HECTOR Y JAVI | I37: 46179 | J37: 13 | K37: 22 | L37: 184 | M37: =CONCATENATE(J37,"-",K37,"-",L37) -> 13-22-184 | N37: =IFERROR(VLOOKUP(M37,'LISTA ITEMS (2)'!$E$2:$G$910,2,FALSE)," ") -> BRIDA P/EXTERIOR NEGRA | O37: =IFERROR(VLOOKUP(M37,'LISTA ITEMS (2)'!$E$2:$G$910,3,FALSE)," ") -> UND | P37: 50 | Q37: INSTALACION DE 8 PLACAS | S37: 50
A38: 36 | B38: 2 | C38: 4 | F38: ILDEFONSO MONILLAS CAMPAN | G38: MANCHA REAL | H38: HECTOR Y JAVI | I38: 46179 | J38: 10 | K38: 37 | L38: 232 | M38: =CONCATENATE(J38,"-",K38,"-",L38) -> 10-37-232 | N38: =IFERROR(VLOOKUP(M38,'LISTA ITEMS (2)'!$E$2:$G$910,2,FALSE)," ") -> SOPORTE CENTRAL NEGRO | O38: =IFERROR(VLOOKUP(M38,'LISTA ITEMS (2)'!$E$2:$G$910,3,FALSE)," ") -> UND | P38: 25 | Q38: INSTALACION DE 8 PLACAS | S38: 25
A39: 37 | B39: 2 | C39: 4 | F39: ILDEFONSO MONILLAS CAMPAN | G39: MANCHA REAL | H39: HECTOR Y JAVI | I39: 46179 | J39: 10 | K39: 37 | L39: 315 | M39: =CONCATENATE(J39,"-",K39,"-",L39) -> 10-37-315 | N39: =IFERROR(VLOOKUP(M39,'LISTA ITEMS (2)'!$E$2:$G$910,2,FALSE)," ") -> SOPORTE FINAL NEGRO | O39: =IFERROR(VLOOKUP(M39,'LISTA ITEMS (2)'!$E$2:$G$910,3,FALSE)," ") -> UND | P39: 25 | Q39: INSTALACION DE 8 PLACAS | S39: 25
A40: 38 | B40: 2 | C40: 4 | F40: ILDEFONSO MONILLAS CAMPAN | G40: MANCHA REAL | H40: HECTOR Y JAVI | I40: 46179 | J40: 6 | K40: 23 | L40: 192 | M40: =CONCATENATE(J40,"-",K40,"-",L40) -> 6-23-192 | N40: =IFERROR(VLOOKUP(M40,'LISTA ITEMS (2)'!$E$2:$G$910,2,FALSE)," ") -> CINTA ACERO PERFORADA PARA MONTAJE | O40: =IFERROR(VLOOKUP(M40,'LISTA ITEMS (2)'!$E$2:$G$910,3,FALSE)," ") -> UND | P40: 3 | Q40: INSTALACION DE 8 PLACAS | S40: 1.5
...

Sheet CONSOLIDADO V2
A1: CONSOLIDADO FEBRERO 2026
A2: CODIGO | B2: DESCRIPCION | C2: UND MEDIDA | D2: Suma de CANT. ENTREGADA | E2: Suma de CANT. DEVOLUC.
A3: 10-15-269 | B3: BARRA ALUMINIO PARA ESTRUCTURA 3.60mt | C3: UND | D3: 170 | E3: 40
A4: 10-34-227 | B4: MICRORAIL 2X30 PERFORADO | C4: UND | D4: 20 | E4: 6
A5: 10-37-232 | B5: SOPORTE CENTRAL NEGRO | C5: UND | D5: 704 | E5: 363
A6: 10-37-287 | B6: SOPORTE CENTRAL GRIS | C6: UND | D6: 15 | E6: 13
A7: 10-37-315 | B7: SOPORTE FINAL NEGRO | C7: UND | D7: 539 | E7: 216
A8: 10-37-316 | B8: SOPORTE FINAL GRIS | C8: UND | D8: 15 | E8: 14
A9: 10-37-330 | B9: SOPORTE EN L ALUMINIO GRIS | C9: UND | D9: 573 | E9: 210
A10: 10-42-268 | B10: PATA ALUMINIO PARA ESTRUCTURA PLACA SOLAR ANGULO 30º | C10: UND | D10: 96 | E10: 34
A11: 10-42-329 | B11: PATA ALUMINIO PARA ESTRUCTURA PLACA SOLAR VELA ANGULO 15º | C11: UND | D11: 11 | E11: 3
A12: 10-43-270 | B12: EMPALME ALUMINIO P/BARRA | C12: UND | D12: 163 | E12: 78
A13: 13-21-181 | B13: TACO P/BRIDA NEGRO | C13: UND | D13: 1500 | E13: 500
A14: 13-22-183 | B14: BRIDA P/INTERIOR NEGRA | C14: UND | D14: 200 | E14: 200
A15: 13-22-184 | B15: BRIDA P/EXTERIOR NEGRA | C15: UND | D15: 2800 | E15: 1300
A16: 13-23-186 | B16: CINTA NEGRA AISLANTE PVC 50MM | C16: UND | D16: 1
A17: 13-23-187 | B17: CINTA VERDE AMARILLA AISLANTE PVC 19MM | C17: UND | D17: 1 | E17: 0
A18: 13-23-190 | B18: CINTA BLANCA AISLANTE PVC 19MM | C18: UND | D18: 2
A19: 13-23-191 | B19: CINTA NEGRA AISLANTE PVC 19MM | C19: UND | D19: 1 | E19: 0
A20: 13-25-255 | B20: ANCLAJE PLASTICO MULTIUSO C/COLLARIN 10X61MM | C20: UND | D20: 50 | E20: 50
A21: 13-67-381 | B21: CANALETA PLASTICA 40X40 | C21: UND | D21: 2
A22: 13-67-382 | B22: CANALETA PLASTICA 60X40 | C22: UND | D22: 2
A23: 14-24-193 | B23: DISCO CORTE ACERO/INOX A1 2EN1 | C23: UND | D23: 54 | E23: 21
A24: 16-13-372 | B24: KIT CABLE BATERIA ARK | C24: UND | D24: 2
A25: 16-31-320 | B25: JUEGO CABLE PARA BATERIA DE LITIO B4850 | C25: UND | D25: 1
A26: 16-31-412 | B26: CABLE UTP RJ45 1.8m (VICTRON ENERGY) | C26: UND | D26: 4
A27: 16-33-369 | B27: OPTIMIZADOR TS4-A-O (TIGO) | C27: UND | D27: 4
A28: 16-45-275 | B28: CAJA DISTRIBUCION INTERIOR 18 ELEM. (SOLERA) | C28: UND | D28: 9 | E28: 2
A29: 16-45-276 | B29: CAJA ESTANCA (COCHERA) EXTERIOR 18PT (IDE) | C29: UND | D29: 9 | E29: 1
A30: 16-45-294 | B30: CAJA DE ESTANCA 133X180X80 EV161 (IDE) | C30: UND | D30: 16 | E30: 1
A31: 16-45-299 | B31: CAJA ESTANCA (COCHERA) EXTERIOR 8PT (IDE) | C31: UND | D31: 2
A32: 16-45-317 | B32: CAJA DISTRIBUCION INTERIOR 8 ELEM. (SOLERA) | C32: UND | D32: 5 | E32: 1
A33: 16-45-383 | B33: CAJA BLANCA P/BATERIA (DYNNES) | C33: UND | D33: 1
A34: 16-46-279 | B34: MANGUERA CORRUGADA 25mm NEGRA | C34: MT | D34: 1 | E34: 1
A35: 16-47-280 | B35: DIFERENCIAL EPR2A063030 2P-63A-30mA (MAXGE) | C35: UND | D35: 5 | E35: 2
A36: 16-47-318 | B36: DIFERENCIAL EPR2A040030 2P-40A-30mA (MAXGE) | C36: UND | D36: 14 | E36: 2
A37: 16-48-281 | B37: PORTA FUSIBLE SGF-32-DC (MAXGE) | C37: UND | D37: 34 | E37: 5
A38: 16-49-282 | B38: CONTACTOR MODULAR RV32 (REVALCO) | C38: UND | D38: 4 | E38: 0
A39: 16-49-288 | B39: CONTACTOR MODULAR EPC1-6322-P7 (MAXGE) | C39: UND | D39: 8
A40: 16-50-283 | B40: FUSIBLE 32A-1000VDC (SASSIN) | C40: UND | D40: 14 | E40: 6
...

Sheet LISTA ITEMS (2)
B1: TOMA DE INVENTARIO
A2: # | B2: GRUPO | C2: ELEMENTO | D2: ITEM | E2: CONCATENADO | F2: DESCRIPCION | G2: UND MEDIDA | H2: PROVEEDOR
A3: 1 | B3: 7 | C3: 20 | D3: 178 | E3: 7-20-178 | F3: ESTUFA CALEFACCION 9 KW | G3: UND | H3: 0
A4: 2 | B4: 7 | C4: 20 | D4: 179 | E4: 7-20-179 | F4: ESTUFA CALEFACCION 12 KW | G4: UND | H4: 0
A5: 3 | B5: 13 | C5: 21 | D5: 180 | E5: 13-21-180 | F5: TACO P/BRIDA BLANCO | G5: UND | H5: RECA
A6: 4 | B6: 13 | C6: 21 | D6: 181 | E6: 13-21-181 | F6: TACO P/BRIDA NEGRO | G6: UND | H6: RECA
A7: 5 | B7: 13 | C7: 22 | D7: 182 | E7: 13-22-182 | F7: BRIDA P/INTERIOR BLANCA | G7: UND | H7: RECA
A8: 6 | B8: 13 | C8: 22 | D8: 183 | E8: 13-22-183 | F8: BRIDA P/INTERIOR NEGRA | G8: UND | H8: RECA
A9: 7 | B9: 13 | C9: 22 | D9: 184 | E9: 13-22-184 | F9: BRIDA P/EXTERIOR NEGRA | G9: UND | H9: RECA
B10: 13 | C10: 23 | D10: 185 | E10: 13-23-185 | F10: CINTA BLANCA AISLANTE PVC 50MM | G10: UND | H10: RECA
B11: 13 | C11: 23 | D11: 186 | E11: 13-23-186 | F11: CINTA NEGRA AISLANTE PVC 50MM | G11: UND | H11: RECA
B12: 13 | C12: 23 | D12: 187 | E12: 13-23-187 | F12: CINTA VERDE AMARILLA AISLANTE PVC 19MM | G12: UND | H12: RECA
B13: 13 | C13: 23 | D13: 188 | E13: 13-23-188 | F13: CINTA ROJA AISLANTE PVC 19MM | G13: UND | H13: RECA
B14: 13 | C14: 23 | D14: 189 | E14: 13-23-189 | F14: CINTA AZUL AISLANTE PVC 19MM | G14: UND | H14: RECA
B15: 13 | C15: 23 | D15: 190 | E15: 13-23-190 | F15: CINTA BLANCA AISLANTE PVC 19MM | G15: UND | H15: RECA
B16: 13 | C16: 23 | D16: 191 | E16: 13-23-191 | F16: CINTA NEGRA AISLANTE PVC 19MM | G16: UND | H16: RECA
B17: 6 | C17: 23 | D17: 192 | E17: 6-23-192 | F17: CINTA ACERO PERFORADA PARA MONTAJE | G17: UND | H17: RECA
B18: 14 | C18: 24 | D18: 193 | E18: 14-24-193 | F18: DISCO CORTE ACERO/INOX A1 2EN1 | G18: UND | H18: RECA
B19: 13 | C19: 25 | D19: 194 | E19: 13-25-194 | F19: ANCLAJE PLASTICO ROSCADO PARA CARTON Y PLADUR TIPO K (WURTH) | G19: UND | H19: WURTH
B20: 15 | C20: 25 | D20: 195 | E20: 15-25-195 | F20: ANCLAJE METALICO ROSCADO PARA PLADUR TIPO K (WURTH) | G20: UND | H20: WURTH
B21: 7 | C21: 26 | D21: 196 | E21: 7-26-196 | F21: ESTACION DE CARGA THOR O7AS-P-V1 GROWATT | G21: UND | H21: GROWATT
... B104: 3 | C104: 31 | D104: 278 | E104: 3-31-278 | F104: CABLE Nª 6 P/PLACA SOLAR ROJO | G104: MT | H104: COTO
B105: 16 | C105: 46 | D105: 279 | E105: 16-46-279 | F105: MANGUERA CORRUGADA 25mm NEGRA | G105: MT | H105: 0
B106: 16 | C106: 47 | D106: 280 | E106: 16-47-280 | F106: DIFERENCIAL EPR2A063030 2P-63A-30mA (MAXGE) | G106: UND | H106: BELTRAN Y CRIADO
B107: 16 | C107: 48 | D107: 281 | E107: 16-48-281 | F107: PORTA FUSIBLE SGF-32-DC (MAXGE) | G107: UND | H107: BELTRAN Y CRIADO
B108: 16 | C108: 49 | D108: 282 | E108: 16-49-282 | F108: CONTACTOR MODULAR RV32 (REVALCO) | G108: UND | H108: INVERSOLAR
B109: 16 | C109: 50 | D109: 283 | E109: 16-50-283 | F109: FUSIBLE 32A-1000VDC (SASSIN) | G109: UND | H109: BELTRAN Y CRIADO
B110: 16 | C110: 51 | D110: 284 | E110: 16-51-284 | F110: LIMITADOR MONOFASICO 3SU1 15/30kA-275V (SASSIN) | G110: UND | H110: BELTRAN Y CRIADO
B111: 16 | C111: 52 | D111: 285 | E111: 16-52-285 | F111: TERMICO EPBE63M1NC63 1P+N C63 (MAXGE) | G111: UND | H111: BELTRAN Y CRIADO
B112: 7 | C112: 35 | D112: 286 | E112: 7-35-286 | F112: INVERSOR SPH 6000TL BL-UP 6KW (GROWATT) | G112: UND | H112: INVERSOLAR
B113: 10 | C113: 37 | D113: 287 | E113: 10-37-287 | F113: SOPORTE CENTRAL GRIS | G113: UND | H113: ESTRUSUR SOLAR
B114: 16 | C114: 49 | D114: 288 | E114: 16-49-288 | F114: CONTACTOR MODULAR EPC1-6322-P7 (MAXGE) | G114: UND | H114: BELTRAN Y CRIADO
B115: 16 | C115: 53 | D115: 289 | E115: 16-53-289 | F115: PINCHO DE COMUNICACIÓN WIFI SHINEWILAN X (GROWATT) | G115: UND | H115: BELTRAN Y CRIADO
B116: 16 | C116: 53 | D116: 290 | E116: 16-53-290 | F116: PINCHO DE COMUNICACIÓN WIFI SHINEWILAN X2 (GROWATT) | G116: UND | H116: BELTRAN Y CRIADO
B117: 9 | C117: 2 | D117: 291 | E117: 9-2-291 | F117: TUBO ELECTRICO PVC 25mm - 3mt(AISCAN) | G117: UND | H117: BELTRAN Y CRIADO
... B145: 16 | C145: 52 | D145: 319 | E145: 16-52-319 | F145: TERMICO EPBE63M1NC25 1P+N C25 (MAXGE) | G145: UND | H145: BELTRAN Y CRIADO
B146: 16 | C146: 31 | D146: 320 | E146: 16-31-320 | F146: JUEGO CABLE PARA BATERIA DE LITIO B4850 | G146: UND | H146: 0
B147: 8 | C147: 27 | D147: 321 | E147: 8-27-321 | F147: TORNILLO AUTOTALADRANTE CON C/HEXAGONAL - R/PARCIAL - ARANDELA CAUCHO 6X120mm A/GALV. | G147: UND | H147: RECA
B148: 16 | C148: 59 | D148: 322 | E148: 16-59-322 | F148: CLAVIJA CAUCHO NEGRA 10/16A | G148: UND | H148: BELTRAN Y CRIADO
B149: 7 | C149: 54 | D149: 323 | E149: 7-54-323 | F149: BATERIA LPF LITHIUM B3 (DYNESS) | G149: UND | H149: INVERSOLAR
...

Sheet FMT BASE ALMACENISTA
A1: FMT-03-ALM | C1: FORMATO ALISTAMIENTO DE MATERIALES (ALMACENISTA) | G1: CONSEC. # | I1: 33 | K1: REGISTRO | L1: PTE
A2: CLIENTE | G2: PARTE TRAB. # | I2: 33 | K2: DEVOLUCION | L2: PTE
A3: CIUDAD | F3: ALISTADO POR: FABIO GUTIERREZ | G3: FECHA REQUER.
A4: CUADIRILLA FORMADA POR:
A5: LINEA | B5: CODIGO | F5: DESCRIPCION | G5: UND MED. | H5: CANT. | I5: VERIFICA TECNICO | J5: FECHA | K5: DEVOLUC. | L5: CANT. REAL CONSUMIDA | M5: SERIAL Nª
A6: 1 | B6: 9 | C6: 2 | D6: 291 | E6: =CONCATENATE(B6,"-",C6,"-",D6) -> 9-2-291 | F6: =IFERROR(VLOOKUP(E6,'LISTA ITEMS (2)'!$E$2:$G$910,2,FALSE)," ") -> TUBO ELECTRICO PVC 25mm - 3mt(AISCAN) | G6: =IFERROR(VLOOKUP(E6,'LISTA ITEMS (2)'!$E$2:$G$910,3,FALSE)," ") -> UND | I6: si | L6: =+H6-K6 -> 0
A7: 2 | B7: 16 | C7: 52 | D7: 292 | E7: =CONCATENATE(B7,"-",C7,"-",D7) -> 16-52-292 | F7: =IFERROR(VLOOKUP(E7,'LISTA ITEMS (2)'!$E$2:$G$910,2,FALSE)," ") -> TERMICO EPBE63M1NC63M1NC40 1P+N C40 (MAXGE) | G7: =IFERROR(VLOOKUP(E7,'LISTA ITEMS (2)'!$E$2:$G$910,3,FALSE)," ") -> UND | I7: si | L7: =+H7-K7 -> 0
A8: 3 | B8: 13 | C8: 21 | D8: 181 | E8: =CONCATENATE(B8,"-",C8,"-",D8) -> 13-21-181 | F8: =IFERROR(VLOOKUP(E8,'LISTA ITEMS (2)'!$E$2:$G$910,2,FALSE)," ") -> TACO P/BRIDA NEGRO | G8: =IFERROR(VLOOKUP(E8,'LISTA ITEMS (2)'!$E$2:$G$910,3,FALSE)," ") -> UND | I8: si | L8: =+H8-K8 -> 0
A9: 4 | B9: 10 | C9: 37 | D9: 315 | E9: =CONCATENATE(B9,"-",C9,"-",D9) -> 10-37-315 | F9: =IFERROR(VLOOKUP(E9,'LISTA ITEMS (2)'!$E$2:$G$910,2,FALSE)," ") -> SOPORTE FINAL NEGRO | G9: =IFERROR(VLOOKUP(E9,'LISTA ITEMS (2)'!$E$2:$G$910,3,FALSE)," ") -> UND | I9: si | L9: =+H9-K9 -> 0
A10: 5 | B10: 10 | C10: 37 | D10: 330 | E10: =CONCATENATE(B10,"-",C10,"-",D10) -> 10-37-330 | F10: =IFERROR(VLOOKUP(E10,'LISTA ITEMS (2)'!$E$2:$G$910,2,FALSE)," ") -> SOPORTE EN L ALUMINIO GRIS | G10: =IFERROR(VLOOKUP(E10,'LISTA ITEMS (2)'!$E$2:$G$910,3,FALSE)," ") -> UND | I10: si | L10: =+H10-K10 -> 0
A11: 6 | B11: 10 | C11: 37 | D11: 232 | E11: =CONCATENATE(B11,"-",C11,"-",D11) -> 10-37-232 | F11: =IFERROR(VLOOKUP(E11,'LISTA ITEMS (2)'!$E$2:$G$910,2,FALSE)," ") -> SOPORTE CENTRAL NEGRO | G11: =IFERROR(VLOOKUP(E11,'LISTA ITEMS (2)'!$E$2:$G$910,3,FALSE)," ") -> UND | I11: si | L11: =+H11-K11 -> 0
A12: 7 | B12: 17 | C12: 44 | D12: 272 | E12: =CONCATENATE(B12,"-",C12,"-",D12) -> 17-44-272 | F12: =IFERROR(VLOOKUP(E12,'LISTA ITEMS (2)'!$E$2:$G$910,2,FALSE)," ") -> SELLANTE QUIMICO GRIS | G12: =IFERROR(VLOOKUP(E12,'LISTA ITEMS (2)'!$E$2:$G$910,3,FALSE)," ") -> UND | I12: si | L12: =+H12-K12 -> 0
A13: 8 | B13: 17 | C13: 44 | D13: 272 | E13: =CONCATENATE(B13,"-",C13,"-",D13) -> 17-44-272 | F13: =IFERROR(VLOOKUP(E13,'LISTA ITEMS (2)'!$E$2:$G$910,2,FALSE)," ") -> SELLANTE QUIMICO GRIS | G13: =IFERROR(VLOOKUP(E13,'LISTA ITEMS (2)'!$E$2:$G$910,3,FALSE)," ") -> UND | I13: si | L13: =+H13-K13 -> 0
A14: 9 | B14: 17 | C14: 44 | D14: 271 | E14: =CONCATENATE(B14,"-",C14,"-",D14) -> 17-44-271 | F14: =IFERROR(VLOOKUP(E14,'LISTA ITEMS (2)'!$E$2:$G$910,2,FALSE)," ") -> SELLANTE QUIMICO BLANCO | G14: =IFERROR(VLOOKUP(E14,'LISTA ITEMS (2)'!$E$2:$G$910,3,FALSE)," ") -> UND | I14: si | L14: =+H14-K14 -> 0
A15: 10 | B15: 17 | C15: 44 | D15: 271 | E15: =CONCATENATE(B15,"-",C15,"-",D15) -> 17-44-271 | F15: =IFERROR(VLOOKUP(E15,'LISTA ITEMS (2)'!$E$2:$G$910,2,FALSE)," ") -> SELLANTE QUIMICO BLANCO | G15: =IFERROR(VLOOKUP(E15,'LISTA ITEMS (2)'!$E$2:$G$910,3,FALSE)," ") -> UND | I15: si | L15: =+H15-K15 -> 0
A16: 11 | B16: 16 | C16: 48 | D16: 281 | E16: =CONCATENATE(B16,"-",C16,"-",D16) -> 16-48-281 | F16: =IFERROR(VLOOKUP(E16,'LISTA ITEMS (2)'!$E$2:$G$910,2,FALSE)," ") -> PORTA FUSIBLE SGF-32-DC (MAXGE) | G16: =IFERROR(VLOOKUP(E16,'LISTA ITEMS (2)'!$E$2:$G$910,3,FALSE)," ") -> UND | I16: si | L16: =+H16-K16 -> 0
A17: 12 | B17: 16 | C17: 53 | D17: 290 | E17: =CONCATENATE(B17,"-",C17,"-",D17) -> 16-53-290 | F17: =IFERROR(VLOOKUP(E17,'LISTA ITEMS (2)'!$E$2:$G$910,2,FALSE)," ") -> PINCHO DE COMUNICACIÓN WIFI SHINEWILAN X2 (GROWATT) | G17: =IFERROR(VLOOKUP(E17,'LISTA ITEMS (2)'!$E$2:$G$910,3,FALSE)," ") -> UND | I17: si | L17: =+H17-K17 -> 0
... A35: 30 | B35: 10 | C35: 15 | D35: 269 | E35: =CONCATENATE(B35,"-",C35,"-",D35) -> 10-15-269 | F35: =IFERROR(VLOOKUP(E35,'LISTA ITEMS (2)'!$E$2:$G$910,2,FALSE)," ") -> BARRA ALUMINIO PARA ESTRUCTURA 3.60mt | G35: =IFERROR(VLOOKUP(E35,'LISTA ITEMS (2)'!$E$2:$G$910,3,FALSE)," ") -> UND | I35: si | L35: =+H35-K35 -> 0
A36: 31 | E36: =CONCATENATE(B36,"-",C36,"-",D36) -> -- | F36: =IFERROR(VLOOKUP(E36,'LISTA ITEMS (2)'!$E$2:$G$910,2,FALSE)," ") -> 0 | G36: =IFERROR(VLOOKUP(E36,'LISTA ITEMS (2)'!$E$2:$G$910,3,FALSE)," ") -> 0 | I36: si | L36: =+H36-K36 -> 0
A37: 32 | E37: =CONCATENATE(B37,"-",C37,"-",D37) -> -- | F37: =IFERROR(VLOOKUP(E37,'LISTA ITEMS (2)'!$E$2:$G$910,2,FALSE)," ") -> 0 | G37: =IFERROR(VLOOKUP(E37,'LISTA ITEMS (2)'!$E$2:$G$910,3,FALSE)," ") -> 0 | I37: si | L37: =+H37-K37 -> 0
A38: 33 | E38: =CONCATENATE(B38,"-",C38,"-",D38) -> -- | F38: =IFERROR(VLOOKUP(E38,'LISTA ITEMS (2)'!$E$2:$G$910,2,FALSE)," ") -> 0 | G38: =IFERROR(VLOOKUP(E38,'LISTA ITEMS (2)'!$E$2:$G$910,3,FALSE)," ") -> 0 | I38: si | L38: =+H38-K38 -> 0
A39: 34 | E39: =CONCATENATE(B39,"-",C39,"-",D39) -> -- | F39: =IFERROR(VLOOKUP(E39,'LISTA ITEMS (2)'!$E$2:$G$910,2,FALSE)," ") -> 0 | G39: =IFERROR(VLOOKUP(E39,'LISTA ITEMS (2)'!$E$2:$G$910,3,FALSE)," ") -> 0 | I39: si | L39: =+H39-K39 -> 0
A40: 35 | E40: =CONCATENATE(B40,"-",C40,"-",D40) -> -- | F40: =IFERROR(VLOOKUP(E40,'LISTA ITEMS (2)'!$E$2:$G$910,2,FALSE)," ") -> 0 | G40: =IFERROR(VLOOKUP(E40,'LISTA ITEMS (2)'!$E$2:$G$910,3,FALSE)," ") -> 0 | I40: si | L40: =+H40-K40 -> 0
A41: 36 | E41: =CONCATENATE(B41,"-",C41,"-",D41) -> -- | F41: =IFERROR(VLOOKUP(E41,'LISTA ITEMS (2)'!$E$2:$G$910,2,FALSE)," ") -> 0 | G41: =IFERROR(VLOOKUP(E41,'LISTA ITEMS (2)'!$E$2:$G$910,3,FALSE)," ") -> 0 | I41: si | L41: =+H41-K41 -> 0
A42: 37 | E42: =CONCATENATE(B42,"-",C42,"-",D42) -> -- | F42: =IFERROR(VLOOKUP(E42,'LISTA ITEMS (2)'!$E$2:$G$910,2,FALSE)," ") -> 0 | G42: =IFERROR(VLOOKUP(E42,'LISTA ITEMS (2)'!$E$2:$G$910,3,FALSE)," ") -> 0 | I42: si | L42: =+H42-K42 -> 0
A43: 38 | E43: =CONCATENATE(B43,"-",C43,"-",D43) -> -- | F43: =IFERROR(VLOOKUP(E43,'LISTA ITEMS (2)'!$E$2:$G$910,2,FALSE)," ") -> 0 | G43: =IFERROR(VLOOKUP(E43,'LISTA ITEMS (2)'!$E$2:$G$910,3,FALSE)," ") -> 0 | I43: si | L43: =+H43-K43 -> 0
A44: 39 | E44: =CONCATENATE(B44,"-",C44,"-",D44) -> -- | F44: =IFERROR(VLOOKUP(E44,'LISTA ITEMS (2)'!$E$2:$G$910,2,FALSE)," ") -> 0 | G44: =IFERROR(VLOOKUP(E44,'LISTA ITEMS (2)'!$E$2:$G$910,3,FALSE)," ") -> 0 | I44: si | L44: =+H44-K44 -> 0
A46: NOTA: MA TERIALES REVISADOS POR EL TECNICO.

Sheet CONSOLIDADO
A1: ALM-07-SAL | E1: RELACION DETALLA DE SALIDAS DIARIAS | S1: CONSOLIDADO 1 | V1: CONSOLIDADO 1
A2: LINEA | B2: # FORMT. ALISTAM. | C2: PARTE TRABAJO # | D2: CLEINTE | E2: CIUDAD | F2: TECNICOS RESPONSABLE | G2: FECHA DE CARGUE | H2: GRUPO | I2: ELEM | J2: ITEM | K2: CONCATENADO | L2: DESCRIPCION | M2: UND MEDIDA | N2: CANT. ENTREGADA | O2: NOTA | P2: SERIAL | Q2: CANT. DEVOLUC. | S2: CODIGO | T2: DESCRIPCION | U2: UND. MED | V2: CANT. SALIDA | W2: CANT. DEVOL
A3: 1 | B3: 1 | C3: 2 | D3: JESUS MORALES BUSTOS | E3: JAEN | F3: HECTOR Y MANUEL | G3: 46055 | H3: 13 | I3: 22 | J3: 184 | K3: =CONCATENATE(H3,"-",I3,"-",J3) -> 13-22-184 | L3: =IFERROR(VLOOKUP(K3,'LISTA ITEMS (2)'!$E$2:$G$910,2,FALSE)," ") -> BRIDA P/EXTERIOR NEGRA | M3: =IFERROR(VLOOKUP(K3,'LISTA ITEMS (2)'!$E$2:$G$910,3,FALSE)," ") -> UND | N3: 100 | O3: INSTALACION DE INTERCAMBIADOR SPE 10KW | Q3: 50 | S3: 13-22-184 | T3: =VLOOKUP(S3,$K$2:$M$195,2,FALSE) -> BRIDA P/EXTERIOR NEGRA | U3: =VLOOKUP(S3,$K$2:$M$195,3,FALSE) -> UND | V3: =SUMIF($K$3:$K$195,S3,$N$3:$N$195) -> 500 | W3: =SUMIF($K$3:$K$195,S3,$Q$3:$Q$195) -> 100
A4: 2 | B4: 1 | C4: 2 | D4: JESUS MORALES BUSTOS | E4: JAEN | F4: HECTOR Y MANUEL | G4: 46055 | H4: 6 | I4: 23 | J4: 192 | K4: =CONCATENATE(H4,"-",I4,"-",J4) -> 6-23-192 | L4: =IFERROR(VLOOKUP(K4,'LISTA ITEMS (2)'!$E$2:$G$910,2,FALSE)," ") -> CINTA ACERO PERFORADA PARA MONTAJE | M4: =IFERROR(VLOOKUP(K4,'LISTA ITEMS (2)'!$E$2:$G$910,3,FALSE)," ") -> UND | N4: 2 | O4: INSTALACION DE INTERCAMBIADOR SPE 10KW | Q4: 2 | S4: 6-23-192 | T4: =VLOOKUP(S4,$K$2:$M$195,2,FALSE) -> CINTA ACERO PERFORADA PARA MONTAJE | U4: =VLOOKUP(S4,$K$2:$M$195,3,FALSE) -> UND | V4: =SUMIF($K$3:$K$195,S4,$N$3:$N$195) -> 9.5 | W4: =SUMIF($K$3:$K$195,S4,$Q$3:$Q$195) -> 3.5
A5: 3 | B5: 1 | C5: 2 | D5: JESUS MORALES BUSTOS | E5: JAEN | F5: HECTOR Y MANUEL | G5: 46055 | H5: 14 | I5: 24 | J5: 193 | K5: =CONCATENATE(H5,"-",I5,"-",J5) -> 14-24-193 | L5: =IFERROR(VLOOKUP(K5,'LISTA ITEMS (2)'!$E$2:$G$910,2,FALSE)," ") -> DISCO CORTE ACERO/INOX A1 2EN1 | M5: =IFERROR(VLOOKUP(K5,'LISTA ITEMS (2)'!$E$2:$G$910,3,FALSE)," ") -> UND | N5: 1 | O5: INSTALACION DE INTERCAMBIADOR SPE 10KW | Q5: 1 | S5: 14-24-193 | T5: =VLOOKUP(S5,$K$2:$M$195,2,FALSE) -> DISCO CORTE ACERO/INOX A1 2EN1 | U5: =VLOOKUP(S5,$K$2:$M$195,3,FALSE) -> UND | V5: =SUMIF($K$3:$K$195,S5,$N$3:$N$195) -> 7 | W5: =SUMIF($K$3:$K$195,S5,$Q$3:$Q$195) -> 2
A6: 4 | B6: 1 | C6: 2 | D6: JESUS MORALES BUSTOS | E6: JAEN | F6: HECTOR Y MANUEL | G6: 46055 | H6: 3 | I6: 31 | J6: 209 | K6: =CONCATENATE(H6,"-",I6,"-",J6) -> 3-31-209 | L6: =IFERROR(VLOOKUP(K6,'LISTA ITEMS (2)'!$E$2:$G$910,2,FALSE)," ") -> CABLE Nª 6 C/ALTERNA MARRON | M6: =IFERROR(VLOOKUP(K6,'LISTA ITEMS (2)'!$E$2:$G$910,3,FALSE)," ") -> MT | N6: 100 | O6: INSTALACION DE INTERCAMBIADOR SPE 10KW | Q6: 100 | S6: 3-31-209 | T6: =VLOOKUP(S6,$K$2:$M$195,2,FALSE) -> CABLE Nª 6 C/ALTERNA MARRON | U6: =VLOOKUP(S6,$K$2:$M$195,3,FALSE) -> MT | V6: =SUMIF($K$3:$K$195,S6,$N$3:$N$195) -> 200 | W6: =SUMIF($K$3:$K$195,S6,$Q$3:$Q$195) -> 130
A7: 5 | B7: 1 | C7: 2 | D7: JESUS MORALES BUSTOS | E7: JAEN | F7: HECTOR Y MANUEL | G7: 46055 | H7: 3 | I7: 31 | J7: 210 | K7: =CONCATENATE(H7,"-",I7,"-",J7) -> 3-31-210 | L7: =IFERROR(VLOOKUP(K7,'LISTA ITEMS (2)'!$E$2:$G$910,2,FALSE)," ") -> CABLE Nª 6 C/ALTERNA GRIS | M7: =IFERROR(VLOOKUP(K7,'LISTA ITEMS (2)'!$E$2:$G$910,3,FALSE)," ") -> MT | N7: 100 | O7: INSTALACION DE INTERCAMBIADOR SPE 10KW | Q7: 100 | S7: 3-31-210 | T7: =VLOOKUP(S7,$K$2:$M$195,2,FALSE) -> CABLE Nª 6 C/ALTERNA GRIS | U7: =VLOOKUP(S7,$K$2:$M$195,3,FALSE) -> MT | V7: =SUMIF($K$3:$K$195,S7,$N$3:$N$195) -> 200 | W7: =SUMIF($K$3:$K$195,S7,$Q$3:$Q$195) -> 130
A8: 6 | B8: 1 | C8: 2 | D8: JESUS MORALES BUSTOS | E8: JAEN | F8: HECTOR Y MANUEL | G8: 46055 | H8: 3 | I8: 31 | J8: 212 | K8: =CONCATENATE(H8,"-",I8,"-",J8) -> 3-31-212 | L8: =IFERROR(VLOOKUP(K8,'LISTA ITEMS (2)'!$E$2:$G$910,2,FALSE)," ") -> CABLE Nª 6 C/ALTERNA AZUL | M8: =IFERROR(VLOOKUP(K8,'LISTA ITEMS (2)'!$E$2:$G$910,3,FALSE)," ") -> MT | N8: 100 | O8: INSTALACION DE INTERCAMBIADOR SPE 10KW | Q8: 100 | S8: 3-31-212 | T8: =VLOOKUP(S8,$K$2:$M$195,2,FALSE) -> CABLE Nª 6 C/ALTERNA AZUL | U8: =VLOOKUP(S8,$K$2:$M$195,3,FALSE) -> MT | V8: =SUMIF($K$3:$K$195,S8,$N$3:$N$195) -> 300 | W8: =SUMIF($K$3:$K$195,S8,$Q$3:$Q$195) -> 200
A9: 7 | B9: 1 | C9: 2 | D9: JESUS MORALES BUSTOS | E9: JAEN | F9: HECTOR Y MANUEL | G9: 46055 | H9: 3 | I9: 31 | J9: 213 | K9: =CONCATENATE(H9,"-",I9,"-",J9) -> 3-31-213 | L9: =IFERROR(VLOOKUP(K9,'LISTA ITEMS (2)'!$E$2:$G$910,2,FALSE)," ") -> CABLE Nª 6 C/ALTERNA NEGRO | M9: =IFERROR(VLOOKUP(K9,'LISTA ITEMS (2)'!$E$2:$G$910,3,FALSE)," ") -> MT | N9: 100 | O9: INSTALACION DE INTERCAMBIADOR SPE 10KW | Q9: 100 | S9: 3-31-213 | T9: =VLOOKUP(S9,$K$2:$M$195,2,FALSE) -> CABLE Nª 6 C/ALTERNA NEGRO | U9: =VLOOKUP(S9,$K$2:$M$195,3,FALSE) -> MT | V9: =SUMIF($K$3:$K$195,S9,$N$3:$N$195) -> 200 | W9: =SUMIF($K$3:$K$195,S9,$Q$3:$Q$195) -> 200
A10: 8 | B10: 1 | C10: 2 | D10: JESUS MORALES BUSTOS | E10: JAEN | F10: HECTOR Y MANUEL | G10: 46055 | H10: 9 | I10: 32 | J10: 223 | K10: =CONCATENATE(H10,"-",I10,"-",J10) -> 9-32-223 | L10: =IFERROR(VLOOKUP(K10,'LISTA ITEMS (2)'!$E$2:$G$910,2,FALSE)," ") -> CURVA PVC M-25 GRIS TIPO A | M10: =IFERROR(VLOOKUP(K10,'LISTA ITEMS (2)'!$E$2:$G$910,3,FALSE)," ") -> UND | N10: =20*3 -> 60 | O10: INSTALACION DE INTERCAMBIADOR SPE 10KW | Q10: 22 | S10: 9-32-223 | T10: =VLOOKUP(S10,$K$2:$M$195,2,FALSE) -> CURVA PVC M-25 GRIS TIPO A | U10: =VLOOKUP(S10,$K$2:$M$195,3,FALSE) -> UND | V10: =SUMIF($K$3:$K$195,S10,$N$3:$N$195) -> 100 | W10: =SUMIF($K$3:$K$195,S10,$Q$3:$Q$195) -> 22
A11: 9 | B11: 1 | C11: 2 | D11: JESUS MORALES BUSTOS | E11: JAEN | F11: HECTOR Y MANUEL | G11: 46055 | H11: 4 | I11: 15 | J11: 267 | K11: =CONCATENATE(H11,"-",I11,"-",J11) -> 4-15-267 | L11: =IFERROR(VLOOKUP(K11,'LISTA ITEMS (2)'!$E$2:$G$910,2,FALSE)," ") -> BARRA PERFORADA PARA REFUERZO 20X10X2MT GALV. | M11: =IFERROR(VLOOKUP(K11,'LISTA ITEMS (2)'!$E$2:$G$910,3,FALSE)," ") -> UND | N11: 30 | O11: INSTALACION DE INTERCAMBIADOR SPE 10KW | S11: 4-15-267 | T11: =VLOOKUP(S11,$K$2:$M$195,2,FALSE) -> BARRA PERFORADA PARA REFUERZO 20X10X2MT GALV. | U11: =VLOOKUP(S11,$K$2:$M$195,3,FALSE) -> UND | V11: =SUMIF($K$3:$K$195,S11,$N$3:$N$195) -> 30 | W11: =SUMIF($K$3:$K$195,S11,$Q$3:$Q$195) -> 0
A12: 10 | B12: 1 | C12: 2 | D12: JESUS MORALES BUSTOS | E12: JAEN | F12: HECTOR Y MANUEL | G12: 46055 | H12: 10 | I12: 42 | J12: 268 | K12: =CONCATENATE(H12,"-",I12,"-",J12) -> 10-42-268 | L12: =IFERROR(VLOOKUP(K12,'LISTA ITEMS (2)'!$E$2:$G$910,2,FALSE)," ") -> PATA ALUMINIO PARA ESTRUCTURA PLACA SOLAR ANGULO 30º | M12: =IFERROR(VLOOKUP(K12,'LISTA ITEMS (2)'!$E$2:$G$910,3,FALSE)," ") -> UND | N12: 20 | O12: INSTALACION DE INTERCAMBIADOR SPE 10KW | Q12: 10 | S12: 10-42-268 | T12: =VLOOKUP(S12,$K$2:$M$195,2,FALSE) -> PATA ALUMINIO PARA ESTRUCTURA PLACA SOLAR ANGULO 30º | U12: =VLOOKUP(S12,$K$2:$M$195,3,FALSE) -> UND | V12: =SUMIF($K$3:$K$195,S12,$N$3:$N$195) -> 28 | W12: =SUMIF($K$3:$K$195,S12,$Q$3:$Q$195) -> 18
